Workbook

Sheet Summary
A1: Line | B1: Dechorionated | C1: DMD imaged | D1: Wells | E1: Week | F1: Plate | G1: Comments from analysis | H1: Example image
A2: WT-c | B2: 24 | C2: 10 | D2: A-B | E2: 1 | F2: 1 | G2: no defects at all, control | H2: 1_1_A9_4
A3: WT-35 | B3: 19 | C3: 10 | D3: A-B | E3: 1 | F3: 2 | G3: no defects at all | H3: 1_2_A3_2 | K3: How to fill in the matrix
A4: WT-37 | B4: 15 | C4: 15 | D4: C3-D6 | E4: 2 | F4: 1 | G4: slight defects (1) in the 11th, 12th or 13th somite | H4: 2_1_C8_52 | K4: Each row = an embryo
A5: WT-39 | B5: 21 | C5: 8 | D5: G-H | E5: 1 | F5: 2 | G5: strong defects on several somites per embryo | H5: 1_2_H7_11_V2 | K5: Each column = a somite
A6: Her7-c | B6: 24 | C6: 11 | D6: C-D | E6: 1 | F6: 1
A7: Her7-35 | B7: 20 | C7: 12 | D7: C-D | E7: 1 | F7: 2 | K7: Defect measurements
A8: Her7-39 | B8: 20 | C8: 8+V2 | D8: E-F | E8: 1 | F8: 2 | K8: 0 | L8: no defect
A9: Loop-c | B9: 12 | C9: 9 | D9: E | E9: 1 | F9: 1 | G9: With loop, you get these 'holes' in the boundaries | H9: 1_1_E4_27 | K9: 1 | L9: mild defect (< 50%)
A10: Loop-35 | B10: 12 | C10: 11 | D10: F | E10: 1 | F10: 1 | G10: Similar but seems to be slightly worse and later? | H10: 1_1_F8_41 | K10: 2 | L10: strong defect (> 50%)
A11: Loop-37 | B11: 12 | C11: 8 | D11: B3-C2 | E11: 2 | F11: 1 | G11: slightly more defects than 35, mainly severe at 6-8 | H11: 2_1_B12_75 | K11: 3 | L11: no segment boundary
A12: Loop-39 | B12: 12 | C12: 11 | D12: G-H | E12: 1 | F12: 1 | G12: wider timing (5-14) and far worse, with missing boundaries | H12: 1_1_G11_55
A13: Her1-c | B13: 15 | C13: 14 | D13: A1-B2 | E13: 2 | F13: 1 | G13: No defects found except for one embryo where the boundries were a little curved | H13: 2_1_A2_9 | K13: ID = week_plate_well_DMD(_2 if in V2 images in week 1, else none)
A14: Her1-35 | B14: 16 | C14: 12 | D14: D7-E10 | E14: 2 | F14: 1 | G14: A few more embryos showed similar defects to the one on control. Similar timing (10) | H14: 2_1_D7_47 | K14: e.g. col. 51 in WT | L14: 1_2_H1_6_2 | M14: (2 at the end for the V2 images during week 1)
A15: Her1-37 | B15: 15 | C15: 14 | D15: E11-G1 | E15: 2 | F15: 1 | G15: Wider timing (8-16), more defects, more severe. | H15: 2_1_F8_54
A16: Her1-39 | B16: 16 | C16: 15 | D16: G2-H5 | E16: 2 | F16: 1 | G16: All embryos present defects, later timing, more severe | H16: 2_1_G7_50 | K16: There is conditional formatting to be able to see trends and compute average/std dev already
B18: Notes
B19: Her1 mutants did not survive the first week, her7 did not survive the second week | J19: Who? | K19: Presentation
B20: Loop mutants did not express DMD in 50% of the embryos (hetero DMD line) | J20: Gresi + Mathilde | K20: 1. Problematic | L20: what did we want to investigate? How /what are the questions to answer?
B21: Incubating temperatures was 28.5°C until Wed evening (~6h) and then 32.5°C for about 16 hours to speed up the process during the night | J21: Gresi + Mathilde | K21: 2. Intro to her and HS | L21: what are they, what do we know
B22: HS was done at somite 8 (W2) and somite ?? (W1) | J22: Gresi + Mathilde | K22: 3. Methods | L22: what did we do, how, limitations (e.g. machine loosing 50% of our fish, fish dying, DMD hetero in her7)
J23: Claire + Matteo | K23: 4. Global results | L23: barplot by condition w/average and std error --> global idea of what we got
J24: Claire + Matteo | K24: 5. Defect positions | L24: histogram : bin by position, average (+std error) or mode by condition --> understand how severity and defect position differ
J25: Gresi + Mathilde | K25: 6. Interpretation | L25: what does this mean? Link to the problematic --> largest part
J26: Gresi + Mathilde | K26: 7. What's next | L26: if we could, what would we want to investigate now?

Sheet WT
A1: Condition | B1: Week | C1: Well | D1: Plate | E1: Orientation (L/R, L if head is on the L) | F1: Brightfield | G1: DMD number | H1: DMD | I1: Features | J1: Defects | K1: Week2 | L1: Comment
A2: Control | B2: 1 | C2: A6 | D2: 1 | E2: R | F2: yes | G2: G1_P1 1 | H2: yes | J2: no | K2: =VALUE(Table146[[#This Row],[Week]]) -> 1
A3: Control | B3: 1 | C3: A7 | D3: 1 | E3: L | F3: yes | G3: 2 | H3: yes | J3: no | K3: =VALUE(Table146[[#This Row],[Week]]) -> 1
A4: Control | B4: 1 | C4: A8 | D4: 1 | E4: L | F4: yes | G4: 3 | H4: yes | J4: no | K4: =VALUE(Table146[[#This Row],[Week]]) -> 1
A5: Control | B5: 1 | C5: A9 | D5: 1 | E5: L | F5: yes | G5: 4 | H5: yes | J5: no | K5: =VALUE(Table146[[#This Row],[Week]]) -> 1
A6: Control | B6: 1 | C6: A10 | D6: 1 | E6: R | F6: yes | G6: 5 | H6: yes | J6: no | K6: =VALUE(Table146[[#This Row],[Week]]) -> 1
A7: Control | B7: 1 | C7: A11 | D7: 1 | E7: L | F7: yes | G7: 6 | H7: yes | J7: no | K7: =VALUE(Table146[[#This Row],[Week]]) -> 1
A8: Control | B8: 1 | C8: A12 | D8: 1 | E8: L | F8: yes | G8: 7 | H8: yes | J8: no | K8: =VALUE(Table146[[#This Row],[Week]]) -> 1
A9: Control | B9: 1 | C9: B1 | D9: 1 | F9: system error | G9: 8 | H9: no | K9: =VALUE(Table146[[#This Row],[Week]]) -> 1 | L9: system error
A10: Control | B10: 1 | C10: B2 | D10: 1 | E10: L | F10: yes | G10: 9 | H10: yes | J10: no | K10: =VALUE(Table146[[#This Row],[Week]]) -> 1
A11: Control | B11: 1 | C11: B3 | D11: 1 | E11: R | F11: yes | G11: 10 | H11: yes | J11: no | K11: =VALUE(Table146[[#This Row],[Week]]) -> 1
A12: Control | B12: 1 | C12: B4 | D12: 1 | E12: L | F12: yes | G12: 11 | H12: yes | J12: no | K12: =VALUE(Table146[[#This Row],[Week]]) -> 1
A13: 35 | B13: 1 | C13: A2 | D13: 2 | E13: L | F13: yes | G13: G1_P2 1 | H13: yes | J13: no | K13: =VALUE(Table146[[#This Row],[Week]]) -> 1
A14: 35 | B14: 1 | C14: A3 | D14: 2 | E14: L | F14: yes | G14: 2 | H14: yes | J14: no | K14: =VALUE(Table146[[#This Row],[Week]]) -> 1
A15: 35 | B15: 1 | C15: A4 | D15: 2 | E15: R | F15: yes | G15: 3 | H15: yes | J15: no | K15: =VALUE(Table146[[#This Row],[Week]]) -> 1
A16: 35 | B16: 1 | C16: A5 | D16: 2 | E16: R | F16: yes | G16: 4 | H16: yes | J16: no | K16: =VALUE(Table146[[#This Row],[Week]]) -> 1
A17: 35 | B17: 1 | C17: A7 | D17: 2 | E17: R | F17: yes | G17: 5 | H17: yes | J17: no | K17: =VALUE(Table146[[#This Row],[Week]]) -> 1 | L17: curved tail
A18: 35 | B18: 1 | C18: A8 | D18: 2 | E18: R | F18: yes | G18: 6 | H18: yes | J18: no | K18: =VALUE(Table146[[#This Row],[Week]]) -> 1
A19: 35 | B19: 1 | C19: A9 | D19: 2 | E19: R | F19: yes | G19: 7 | H19: yes | J19: no | K19: =VALUE(Table146[[#This Row],[Week]]) -> 1 | L19: blurry
A20: 35 | B20: 1 | C20: A10 | D20: 2 | E20: L | F20: yes | G20: 8 | H20: yes | J20: no | K20: =VALUE(Table146[[#This Row],[Week]]) -> 1
A21: 35 | B21: 1 | C21: A11 | D21: 2 | E21: R | F21: yes | G21: 9 | H21: yes | J21: no | K21: =VALUE(Table146[[#This Row],[Week]]) -> 1
A22: 35 | B22: 1 | C22: A12 | D22: 2 | E22: R | F22: yes | G22: 10 | H22: yes | J22: no | K22: =VALUE(Table146[[#This Row],[Week]]) -> 1
A23: 37 | B23: 2 | C23: C3 | D23: 1 | E23: R | F23: yes | G23: 19 | H23: yes | J23: yes | K23: =VALUE(Table146[[#This Row],[Week]]) -> 2
A24: 37 | B24: 2 | C24: C4 | D24: 1 | E24: L | F24: yes | G24: 27 | H24: yes | J24: yes | K24: =VALUE(Table146[[#This Row],[Week]]) -> 2
A25: 37 | B25: 2 | C25: C5 | D25: 1 | E25: missing | F25: missing | G25: missing | H25: missing | I25: missing | J25: missing | K25: =VALUE(Table146[[#This Row],[Week]]) -> 2
A26: 37 | B26: 2 | C26: C6 | D26: 1 | E26: R | F26: yes | G26: 42 | H26: yes | J26: yes | K26: =VALUE(Table146[[#This Row],[Week]]) -> 2
A27: 37 | B27: 2 | C27: C7 | D27: 1 | E27: R | F27: yes | G27: 46 | H27: yes | J27: yes | K27: =VALUE(Table146[[#This Row],[Week]]) -> 2
A28: 37 | B28: 2 | C28: C8 | D28: 1 | E28: L | F28: yes | G28: 52 | H28: yes | J28: yes | K28: =VALUE(Table146[[#This Row],[Week]]) -> 2
A29: 37 | B29: 2 | C29: C9 | D29: 1 | E29: L | F29: yes | G29: 58 | H29: yes | J29: yes | K29: =VALUE(Table146[[#This Row],[Week]]) -> 2
A30: 37 | B30: 2 | C30: C10 | D30: 1 | E30: L | F30: yes | G30: 64 | H30: yes | J30: yes | K30: =VALUE(Table146[[#This Row],[Week]]) -> 2
A31: 37 | B31: 2 | C31: C11 | D31: 1 | E31: L | F31: yes | G31: 69 | H31: yes | J31: no | K31: =VALUE(Table146[[#This Row],[Week]]) -> 2
A32: 37 | B32: 2 | C32: C12 | D32: 1 | E32: L | F32: yes | G32: 76 | H32: yes | J32: yes | K32: =VALUE(Table146[[#This Row],[Week]]) -> 2
A33: 37 | B33: 2 | C33: D1 | D33: 1 | E33: L | F33: yes | G33: 4 | H33: yes | J33: no | K33: =VALUE(Table146[[#This Row],[Week]]) -> 2
A34: 37 | B34: 2 | C34: D2 | D34: 1 | E34: R | F34: yes | G34: 12 | H34: yes | J34: no | K34: =VALUE(Table146[[#This Row],[Week]]) -> 2
A35: 37 | B35: 2 | C35: D3 | D35: 1 | E35: R | F35: yes | G35: 20 | H35: yes | J35: yes | K35: =VALUE(Table146[[#This Row],[Week]]) -> 2
A36: 37 | B36: 2 | C36: D4 | D36: 1 | E36: R | F36: yes | G36: 28 | H36: yes | J36: no | K36: =VALUE(Table146[[#This Row],[Week]]) -> 2
A37: 37 | B37: 2 | C37: D5 | D37: 1 | E37: L | F37: yes | G37: 35 | H37: yes | J37: yes | K37: =VALUE(Table146[[#This Row],[Week]]) -> 2
A38: 37 | B38: 2 | C38: D6 | D38: 1 | E38: L | F38: yes | G38: 43 | H38: yes | J38: no | K38: =VALUE(Table146[[#This Row],[Week]]) -> 2
A39: 39 | B39: 1 | C39: G1 | D39: 2 | E39: L | F39: yes | G39: 35 | H39: yes | J39: can't distiguish | K39: =VALUE(Table146[[#This Row],[Week]]) -> 1 | L39: very blurry
A40: 39 | B40: 1 | C40: G2 | D40: 2 | E40: R | F40: yes | G40: 36 | H40: yes | J40: can't distiguish | K40: =VALUE(Table146[[#This Row],[Week]]) -> 1 | L40: very blurry
...

Sheet Her7
A1: Condition | B1: Week | C1: Well | D1: Plate | E1: Orientation (L/R, L if head is on the L) | F1: Brightfield | G1: DMD number | H1: DMD | I1: Features | J1: Defects | K1: Week2 | L1: Comment
A2: Control | B2: 1 | C2: C1 | D2: 1 | E2: R | F2: Yes | G2: 12 | H2: Yes | J2: no | K2: 1
A3: Control | B3: 1 | C3: C2 | D3: 1 | E3: L | F3: Yes | G3: 13 | H3: Yes | J3: no | K3: 1
A4: Control | B4: 1 | C4: C3 | D4: 1 | E4: L | F4: Yes | G4: 14 | H4: Yes | J4: no | K4: 1
A5: Control | B5: 1 | C5: C4 | D5: 1 | E5: L | F5: Yes | G5: 15 | H5: Yes | J5: no | K5: 1
A6: Control | B6: 1 | C6: C5 | D6: 1 | F6: No | G6: 16 | H6: No | K6: 1
A7: Control | B7: 1 | C7: C6 | D7: 1 | E7: L | F7: Yes | G7: 17 | H7: Yes | J7: no | K7: 1
A8: Control | B8: 1 | C8: C7 | D8: 1 | E8: R | F8: Yes | G8: 18 | H8: Yes | J8: no | K8: 1
A9: Control | B9: 1 | C9: C8 | D9: 1 | E9: L | F9: Yes | G9: 19 | H9: Yes | J9: no | K9: 1
A10: Control | B10: 1 | C10: C9 | D10: 1 | E10: R | F10: Yes | G10: 20 | H10: Yes | J10: no | K10: 1
A11: Control | B11: 1 | C11: C10 | D11: 1 | E11: L | F11: Yes | G11: 21 | H11: Yes | J11: no | K11: 1
A12: Control | B12: 1 | C12: C11 | D12: 1 | E12: L | F12: Yes | G12: 22 | H12: Yes | J12: no | K12: 1
A13: Control | B13: 1 | C13: C12 | D13: 1 | E13: L | F13: Yes | G13: 23 | H13: Yes | J13: no | K13: 1
A14: 35 | B14: 1 | C14: C1 | D14: 2 | E14: R | F14: Yes | G14: 11 | H14: Yes | J14: no | K14: 1
A15: 35 | B15: 1 | C15: C2 | D15: 2 | E15: L | F15: Yes | G15: 12 | H15: Yes | J15: no | K15: 1
A16: 35 | B16: 1 | C16: C3 | D16: 2 | E16: R | F16: Yes | G16: 13 | H16: Yes | J16: no | K16: 1
A17: 35 | B17: 1 | C17: C4 | D17: 2 | E17: L | F17: Yes | G17: 14 | H17: Yes | J17: no | K17: 1
A18: 35 | B18: 1 | C18: C5 | D18: 2 | E18: L | F18: Yes | G18: 15 | H18: Yes | J18: no | K18: 1
... A20: 35 | B20: 1 | C20: C7 | D20: 2 | E20: R | F20: Yes | G20: 17 | H20: Yes | J20: no | K20: 1
A21: 35 | B21: 1 | C21: C8 | D21: 2 | E21: L | F21: Yes | G21: 18 | H21: Yes | J21: yes | K21: 1 | L21: crossovers between somites close to head
A22: 35 | B22: 1 | C22: C9 | D22: 2 | E22: R | F22: Yes | G22: 19 | H22: Yes | J22: no | K22: 1
A23: 35 | B23: 1 | C23: C10 | D23: 2 | E23: L | F23: Yes | G23: 20 | H23: Yes | J23: no | K23: 1
A24: 35 | B24: 1 | C24: C11 | D24: 2 | E24: L | F24: Yes | G24: 21 | H24: Yes | J24: no | K24: 1
A25: 35 | B25: 1 | C25: C12 | D25: 2 | E25: L | F25: Yes | G25: 22 | H25: Yes | J25: no | K25: 1
A26: 39 | B26: 1 | C26: E1 | D26: 2 | E26: R | F26: Yes | G26: 23 | H26: Yes | J26: yes | K26: 1 | L26: not sure (in the middle)
A27: 39 | B27: 1 | C27: E2 | D27: 2 | E27: L | F27: Yes | G27: =G26+1 -> 24 | H27: Yes | J27: yes | K27: 1 | L27: some DMD visible between the somites
A28: 39 | B28: 1 | C28: E3 | D28: 2 | E28: R | F28: Yes | G28: =G27+1 -> 25 | H28: Yes | J28: yes | K28: 1
A29: 39 | B29: 1 | C29: E4 | D29: 2 | E29: R | F29: Yes | G29: =G28+1 -> 26 | H29: Yes | J29: yes | K29: 1 | L29: one shorten somite
A30: 39 | B30: 1 | C30: E5 | D30: 2 | E30: L | F30: Yes | G30: =G29+1 -> 27 | H30: Yes | K30: 1 | L30: very blurry
A31: 39 | B31: 1 | C31: E6 | D31: 2 | E31: L | F31: Yes | G31: =G30+1 -> 28 | H31: Yes | J31: yes | K31: 1
A32: 39 | B32: 1 | C32: E7 | D32: 2 | E32: R | F32: Yes | G32: =G31+1 -> 29 | H32: Yes | J32: yes | K32: 1
A33: 39 | B33: 1 | C33: E8 | D33: 2 | E33: R | F33: Yes | G33: =G32+1 -> 30 | H33: Yes | J33: yes | K33: 1
A34: 39 | B34: 1 | C34: E9 | D34: 2 | E34: L | F34: Yes | G34: =G33+1 -> 31 | H34: Yes | J34: no | K34: 1
A35: 39 | B35: 1 | C35: E10 | D35: 2 | E35: L | F35: Yes | G35: =G34+1 -> 32 | H35: Yes | K35: 1 | L35: very blurry
A36: 39 | B36: 1 | C36: E11 | D36: 2 | E36: R | F36: Yes | G36: =G35+1 -> 33 | H36: Yes | K36: 1 | L36: very blurry
A37: 39 | B37: 1 | C37: E12 | D37: 2 | E37: L | F37: Yes | G37: =G36+1 -> 34 | H37: Yes | K37: 1 | L37: very blurry
A38: 39 | B38: 1 | C38: F2 | D38: 2 | E38: L | F38: Yes | G38: V2 | H38: Yes | J38: yes | K38: 1
A39: 39 | B39: 1 | C39: F3 | D39: 2 | E39: R | F39: Yes | G39: V2 | H39: Yes | J39: yes | K39: 1
A40: 39 | B40: 1 | C40: F5 | D40: 2 | E40: L | F40: Yes | G40: V2 | H40: Yes | J40: yes | K40: 1
A41: 39 | B41: 1 | C41: F6 | D41: 2 | E41: L | F41: Yes | G41: V2 | H41: Yes | J41: yes | K41: 1
...

Sheet Her1
A1: Condition | B1: Week | C1: Well | D1: Plate | E1: Orientation (L/R, L if head is on the L) | F1: Brightfield | G1: DMD number | H1: DMD | I1: Features | J1: Defects | K1: Week2 | L1: Comment
A2: Control | B2: 2 | C2: A1 | D2: 1
A3: Control | B3: 2 | C3: A2 | D3: 1
A4: Control | B4: 2 | C4: A3 | D4: 1
A5: Control | B5: 2 | C5: A4 | D5: 1
A6: Control | B6: 2 | C6: A5 | D6: 1
A7: Control | B7: 2 | C7: A6 | D7: 1
A8: Control | B8: 2 | C8: A7 | D8: 1
A9: Control | B9: 2 | C9: A8 | D9: 1
A10: Control | B10: 2 | C10: A9 | D10: 1
A11: Control | B11: 2 | C11: A10 | D11: 1
A12: Control | B12: 2 | C12: A11 | D12: 1
A13: Control | B13: 2 | C13: A12 | D13: 1
... A62: 39 | B62: 2 | C62: H5 | D62: 1

Sheet Loop
A1: Condition | B1: Week | C1: Well | D1: Plate | E1: Orientation (L/R, L if head is on the L) | F1: Brightfield | G1: DMD number | H1: DMD | I1: Features | J1: Defects | K1: Comment
A2: Control | B2: 1 | C2: E1 | D2: 1 | E2: L | F2: Yes | G2: 24 | H2: Yes | J2: Yes | K2: from her7 theoretically..
A3: Control | B3: 1 | C3: E2 | D3: 1 | E3: L | F3: Yes | G3: 25 | H3: Yes | J3: Yes
A4: Control | B4: 1 | C4: E3 | D4: 1 | E4: R | F4: Yes | G4: 26 | H4: Yes | J4: Yes
A5: Control | B5: 1 | C5: E4 | D5: 1 | E5: L | F5: Yes | G5: 27 | H5: Yes | J5: Yes
A6: Control | B6: 1 | C6: E5 | D6: 1 | E6: R | F6: Yes | G6: 28 | H6: Yes | I6: No DMD | K6: Not fluo enough
A7: Control | B7: 1 | C7: E6 | D7: 1 | E7: L | F7: Yes | G7: 29 | H7: Yes | J7: Yes
A8: Control | B8: 1 | C8: E7 | D8: 1 | F8: No | H8: No | K8: X
A9: Control | B9: 1 | C9: E8 | D9: 1 | E9: L | F9: Yes | G9: 30 | H9: Yes | J9: Yes
A10: Control | B10: 1 | C10: E9 | D10: 1 | E10: L | F10: Yes | G10: 31 | H10: Yes | J10: No
A11: Control | B11: 1 | C11: E10 | D11: 1 | E11: L | F11: Yes | G11: 32 | H11: Yes | J11: Yes
A12: Control | B12: 1 | C12: E11 | D12: 1 | F12: No | H12: No | K12: X
A13: Control | B13: 1 | C13: E12 | D13: 1 | E13: R | F13: Yes | G13: 33 | H13: Yes | J13: Yes
A14: 35 | B14: 1 | C14: F1 | D14: 1 | E14: R | F14: Yes | G14: 34 | H14: Yes | J14: Yes
A15: 35 | B15: 1 | C15: F2 | D15: 1 | E15: L | F15: Yes | G15: 35 | H15: Yes | J15: Yes
A16: 35 | B16: 1 | C16: F3 | D16: 1 | E16: L | F16: Yes | G16: 36 | H16: Yes | I16: deformed | J16: Yes
A17: 35 | B17: 1 | C17: F4 | D17: 1 | E17: R | F17: Yes | G17: 37 | H17: Yes | J17: No
A18: 35 | B18: 1 | C18: F5 | D18: 1 | E18: R | F18: Yes | G18: 38 | H18: Yes | J18: Yes | K18: really not sure about all of these
A19: 35 | B19: 1 | C19: F6 | D19: 1 | E19: R | F19: Yes | G19: 39 | H19: Yes | J19: Yes
A20: 35 | B20: 1 | C20: F7 | D20: 1 | E20: R | F20: Yes | G20: 40 | H20: Yes | J20: Yes
A21: 35 | B21: 1 | C21: F8 | D21: 1 | E21: L | F21: Yes | G21: 41 | H21: Yes | J21: Yes
A22: 35 | B22: 1 | C22: F9 | D22: 1 | E22: L | F22: Yes | G22: 42 | H22: Yes | J22: Yes
A23: 35 | B23: 1 | C23: F10 | D23: 1 | E23: L | F23: Yes | G23: 43 | H23: Yes | I23: No DMD | K23: Not fluo enough
A24: 35 | B24: 1 | C24: F11 | D24: 1 | E24: L | F24: Yes | G24: 44 | H24: Yes | J24: Yes
A25: 35 | B25: 1 | C25: F12 | D25: 1 | E25: L | F25: Yes | G25: 45 | H25: Yes | J25: Yes
A26: 37 | B26: 2 | C26: B3 | D26: 1 | E26: L | F26: Yes | G26: 18 | H26: Yes | J26: Yes
A27: 37 | B27: 2 | C27: B4 | D27: 1 | E27: R | F27: Yes | G27: 26 | H27: Yes | J27: Yes
A28: 37 | B28: 2 | C28: B5 | D28: 1 | F28: Yes | G28: 34 | H28: No | I28: No DMD | K28: No DMD
A29: 37 | B29: 2 | C29: B6 | D29: 1 | E29: L | F29: Yes | G29: 41 | H29: Yes | J29: Yes
A30: 37 | B30: 2 | C30: B7 | D30: 1 | F30: No | H30: No | J30: Yes
A31: 37 | B31: 2 | C31: B8 | D31: 1 | F31: No | H31: No | K31: brightfield out of frame
A32: 37 | B32: 2 | C32: B9 | D32: 1 | E32: L | F32: Yes | G32: 57 | H32: Yes | J32: Yes
A33: 37 | B33: 2 | C33: B10 | D33: 1 | E33: L | F33: Yes | G33: 63 | H33: Yes | J33: Yes
A34: 37 | B34: 2 | C34: B11 | D34: 1 | F34: Yes | H34: No | J34: ? | K34: can't find the fish
A35: 37 | B35: 2 | C35: B12 | D35: 1 | E35: R | F35: Yes | G35: 75 | H35: Yes | J35: Yes
A36: 37 | B36: 2 | C36: C1 | D36: 1 | E36: L | F36: Yes | G36: 3 | H36: Yes | J36: Yes
A37: 37 | B37: 2 | C37: C2 | D37: 1 | E37: L | F37: Yes | G37: 11 | H37: Yes | J37: Yes
A38: 39 | B38: 1 | C38: G1 | D38: 1 | E38: L | F38: Yes | G38: 46 | H38: Yes | J38: Yes
A39: 39 | B39: 1 | C39: G2 | D39: 1 | E39: R | F39: Yes | G39: 47 | H39: Yes | J39: Yes
A40: 39 | B40: 1 | C40: G3 | D40: 1 | F40: No | H40: No
...

Sheet Analysis
C1: 1 | D1: 2 | E1: 3 | F1: 4 | G1: 5 | H1: 6 | I1: 7 | J1: 8 | K1: 9 | L1: 10 | M1: 11 | N1: 12 | O1: 13 | P1: 14 | Q1: 15 | R1: 16 | S1: 17 | T1: 18 | U1: 19 | V1: 20 | W1: 21 | X1: 22 | Y1: 23 | Z1: 24 | AA1: 25 | AB1: 26 | AC1: 27 | AD1: Total
A2: WT_c | B2: Average | C2: =WT_c!B13 -> 0 | D2: =WT_c!C13 -> 0 | E2: =WT_c!D13 -> 0 | F2: =WT_c!E13 -> 0 | G2: =WT_c!F13 -> 0 | H2: =WT_c!G13 -> 0 | I2: =WT_c!H13 -> 0 | J2: =WT_c!I13 -> 0 | ... AD2: =WT_c!AC13 -> 0
A3: WT_35 | B3: Average
A4: WT_37 | B4: Average
A5: WT_39 | B5: Average
A6: her1_c | B6: Average
A7: her1_35 | B7: Average
A8: her1_37 | B8: Average
A9: her1_39 | B9: Average
A10: loop_c | B10: Average
A11: loop_35 | B11: Average
A12: loop_37 | B12: Average
A13: loop_39 | B13: Average
A14: her7_c | B14: Average
... A16: her7_39 | B16: Average

Sheet WT_c
A1: ID | B1: 1 | C1: 2 | D1: 3 | E1: 4 | F1: 5 | G1: 6 | H1: 7 | I1: 8 | J1: 9 | K1: 10 | L1: 11 | M1: 12 | N1: 13 | O1: 14 | P1: 15 | Q1: 16 | R1: 17 | S1: 18 | T1: 19 | U1: 20 | V1: 21 | W1: 22 | X1: 23 | Y1: 24 | Z1: 25 | AA1: 26 | AB1: 27 | AC1: total
A2: 1_1_A6_1 | B2: 0 | C2: 0 | D2: 0 | E2: 0 | F2: 0 | G2: 0 | H2: 0 | I2: 0 | J2: 0 | K2: 0 | L2: 0 | M2: 0 | N2: 0 | O2: 0 | P2: 0 | Q2: 0 | R2: 0 | S2: 0 | T2: 0 | U2: 0 | V2: 0 | W2: 0 | X2: 0 | Y2: 0 | Z2: 0 | AA2: 0 | AB2: 0 | AC2: =SUM(B2:AB2) -> 0
A3: 1_1_A7_2 | B3: 0 | C3: 0 | D3: 0 | E3: 0 | F3: 0 | G3: 0 | H3: 0 | I3: 0 | J3: 0 | K3: 0 | L3: 0 | M3: 0 | N3: 0 | O3: 0 | P3: 0 | Q3: 0 | R3: 0 | S3: 0 | T3: 0 | U3: 0 | V3: 0 | W3: 0 | X3: 0 | Y3: 0 | Z3: 0 | AA3: 0 | AB3: 0 | AC3: =SUM(B3:AB3) -> 0
A4: 1_1_A8_3 | B4: 0 | C4: 0 | D4: 0 | E4: 0 | F4: 0 | G4: 0 | H4: 0 | I4: 0 | J4: 0 | K4: 0 | L4: 0 | M4: 0 | N4: 0 | O4: 0 | P4: 0 | Q4: 0 | R4: 0 | S4: 0 | T4: 0 | U4: 0 | V4: 0 | W4: 0 | X4: 0 | Y4: 0 | Z4: 0 | AA4: 0 | AB4: 0 | AC4: =SUM(B4:AB4) -> 0
A5: 1_1_A9_4 | B5: 0 | C5: 0 | D5: 0 | E5: 0 | F5: 0 | G5: 0 | H5: 0 | I5: 0 | J5: 0 | K5: 0 | L5: 0 | M5: 0 | N5: 0 | O5: 0 | P5: 0 | Q5: 0 | R5: 0 | S5: 0 | T5: 0 | U5: 0 | V5: 0 | W5: 0 | X5: 0 | Y5: 0 | Z5: 0 | AA5: 0 | AB5: 0 | AC5: =SUM(B5:AB5) -> 0
A6: 1_1_A10_5 | B6: 0 | C6: 0 | D6: 0 | E6: 0 | F6: 0 | G6: 0 | H6: 0 | I6: 0 | J6: 0 | K6: 0 | L6: 0 | M6: 0 | N6: 0 | O6: 0 | P6: 0 | Q6: 0 | R6: 0 | S6: 0 | T6: 0 | U6: 0 | V6: 0 | W6: 0 | X6: 0 | Y6: 0 | Z6: 0 | AA6: 0 | AB6: 0 | AC6: =SUM(B6:AB6) -> 0
A7: 1_1_A11_6 | B7: 0 | C7: 0 | D7: 0 | E7: 0 | F7: 0 | G7: 0 | H7: 0 | I7: 0 | J7: 0 | K7: 0 | L7: 0 | M7: 0 | N7: 0 | O7: 0 | P7: 0 | Q7: 0 | R7: 0 | S7: 0 | T7: 0 | U7: 0 | V7: 0 | W7: 0 | X7: 0 | Y7: 0 | Z7: 0 | AA7: 0 | AB7: 0 | AC7: =SUM(B7:AB7) -> 0
A8: 1_1_A12_7 | B8: 0 | C8: 0 | D8: 0 | E8: 0 | F8: 0 | G8: 0 | H8: 0 | I8: 0 | J8: 0 | K8: 0 | L8: 0 | M8: 0 | N8: 0 | O8: 0 | P8: 0 | Q8: 0 | R8: 0 | S8: 0 | T8: 0 | U8: 0 | V8: 0 | W8: 0 | X8: 0 | Y8: 0 | Z8: 0 | AA8: 0 | AB8: 0 | AC8: =SUM(B8:AB8) -> 0
A9: 1_1_B1_8 | B9: 0 | C9: 0 | D9: 0 | E9: 0 | F9: 0 | G9: 0 | H9: 0 | I9: 0 | J9: 0 | K9: 0 | L9: 0 | M9: 0 | N9: 0 | O9: 0 | P9: 0 | Q9: 0 | R9: 0 | S9: 0 | T9: 0 | U9: 0 | V9: 0 | W9: 0 | X9: 0 | Y9: 0 | Z9: 0 | AA9: 0 | AB9: 0 | AC9: =SUM(B9:AB9) -> 0
A10: 1_1_B2_9 | B10: 0 | C10: 0 | D10: 0 | E10: 0 | F10: 0 | G10: 0 | H10: 0 | I10: 0 | J10: 0 | K10: 0 | L10: 0 | M10: 0 | N10: 0 | O10: 0 | P10: 0 | Q10: 0 | R10: 0 | S10: 0 | T10: 0 | U10: 0 | V10: 0 | W10: 0 | X10: 0 | Y10: 0 | Z10: 0 | AA10: 0 | AB10: 0 | AC10: =SUM(B10:AB10) -> 0
A11: 1_1_B3_10 | B11: 0 | C11: 0 | D11: 0 | E11: 0 | F11: 0 | G11: 0 | H11: 0 | I11: 0 | J11: 0 | K11: 0 | L11: 0 | M11: 0 | N11: 0 | O11: 0 | P11: 0 | Q11: 0 | R11: 0 | S11: 0 | T11: 0 | U11: 0 | V11: 0 | W11: 0 | X11: 0 | Y11: 0 | Z11: 0 | AA11: 0 | AB11: 0 | AC11: =SUM(B11:AB11) -> 0
A12: 1_1_B4_11 | B12: 0 | C12: 0 | D12: 0 | E12: 0 | F12: 0 | G12: 0 | H12: 0 | I12: 0 | J12: 0 | K12: 0 | L12: 0 | M12: 0 | N12: 0 | O12: 0 | P12: 0 | Q12: 0 | R12: 0 | S12: 0 | T12: 0 | U12: 0 | V12: 0 | W12: 0 | X12: 0 | Y12: 0 | Z12: 0 | AA12: 0 | AB12: 0 | AC12: =SUM(B12:AB12) -> 0
A13: Average | B13: =AVERAGE(B2:B12) -> 0 | C13: =AVERAGE(C2:C12) -> 0 | D13: =AVERAGE(D2:D12) -> 0 | E13: =AVERAGE(E2:E12) -> 0 | F13: =AVERAGE(F2:F12) -> 0 | G13: =AVERAGE(G2:G12) -> 0 | H13: =AVERAGE(H2:H12) -> 0 | I13: =AVERAGE(I2:I12) -> 0 | ... AC13: =AVERAGE(AC2:AC12) -> 0
A14: Median | B14: =MEDIAN(B2:B12) -> 0 | C14: =MEDIAN(C2:C12) -> 0 | D14: =MEDIAN(D2:D12) -> 0 | E14: =MEDIAN(E2:E12) -> 0 | F14: =MEDIAN(F2:F12) -> 0 | G14: =MEDIAN(G2:G12) -> 0 | H14: =MEDIAN(H2:H12) -> 0 | I14: =MEDIAN(I2:I12) -> 0 | ... AC14: =MEDIAN(AC2:AC12) -> 0
A15: Mode | B15: =_xlfn.MODE.SNGL(B2:B12) -> 0 | C15: =_xlfn.MODE.SNGL(C2:C12) -> 0 | D15: =_xlfn.MODE.SNGL(D2:D12) -> 0 | E15: =_xlfn.MODE.SNGL(E2:E12) -> 0 | F15: =_xlfn.MODE.SNGL(F2:F12) -> 0 | G15: =_xlfn.MODE.SNGL(G2:G12) -> 0 | H15: =_xlfn.MODE.SNGL(H2:H12) -> 0 | I15: =_xlfn.MODE.SNGL(I2:I12) -> 0 | ... AC15: =_xlfn.MODE.SNGL(AC2:AC12) -> 0
A16: Std dev | B16: =_xlfn.STDEV.P(B2:B12) -> 0 | C16: =_xlfn.STDEV.P(C2:C12) -> 0 | D16: =_xlfn.STDEV.P(D2:D12) -> 0 | E16: =_xlfn.STDEV.P(E2:E12) -> 0 | F16: =_xlfn.STDEV.P(F2:F12) -> 0 | G16: =_xlfn.STDEV.P(G2:G12) -> 0 | H16: =_xlfn.STDEV.P(H2:H12) -> 0 | I16: =_xlfn.STDEV.P(I2:I12) -> 0 | ... AC16: =_xlfn.STDEV.P(AC2:AC12) -> 0

Sheet WT_35
A1: ID | B1: 1 | C1: 2 | D1: 3 | E1: 4 | F1: 5 | G1: 6 | H1: 7 | I1: 8 | J1: 9 | K1: 10 | L1: 11 | M1: 12 | N1: 13 | O1: 14 | P1: 15 | Q1: 16 | R1: 17 | S1: 18 | T1: 19 | U1: 20 | V1: 21 | W1: 22 | X1: 23 | Y1: 24 | Z1: 25 | AA1: 26 | AB1: 27 | AC1: total
A2: 1_2_A2_1 | B2: 0 | C2: 0 | D2: 0 | E2: 0 | F2: 0 | G2: 0 | H2: 0 | I2: 0 | J2: 0 | K2: 0 | L2: 0 | M2: 0 | N2: 0 | O2: 0 | P2: 0 | Q2: 0 | R2: 0 | S2: 0 | T2: 0 | U2: 0 | V2: 0 | W2: 0 | X2: 0 | Y2: 0 | Z2: 0 | AA2: 0 | AB2: 0 | AC2: =SUM(B2:AB2) -> 0
A3: 1_2_A3_2 | B3: 0 | C3: 0 | D3: 0 | E3: 0 | F3: 0 | G3: 0 | H3: 0 | I3: 0 | J3: 0 | K3: 0 | L3: 0 | M3: 0 | N3: 0 | O3: 0 | P3: 0 | Q3: 0 | R3: 0 | S3: 0 | T3: 0 | U3: 0 | V3: 0 | W3: 0 | X3: 0 | Y3: 0 | Z3: 0 | AA3: 0 | AB3: 0 | AC3: =SUM(B3:AB3) -> 0
A4: 1_2_A4_3 | B4: 0 | C4: 0 | D4: 0 | E4: 0 | F4: 0 | G4: 0 | H4: 0 | I4: 0 | J4: 0 | K4: 0 | L4: 0 | M4: 0 | N4: 0 | O4: 0 | P4: 0 | Q4: 0 | R4: 0 | S4: 0 | T4: 0 | U4: 0 | V4: 0 | W4: 0 | X4: 0 | Y4: 0 | Z4: 0 | AA4: 0 | AB4: 0 | AC4: =SUM(B4:AB4) -> 0
A5: 1_2_A5_4 | B5: 0 | C5: 0 | D5: 0 | E5: 0 | F5: 0 | G5: 0 | H5: 0 | I5: 0 | J5: 0 | K5: 0 | L5: 0 | M5: 0 | N5: 0 | O5: 0 | P5: 0 | Q5: 0 | R5: 0 | S5: 0 | T5: 0 | U5: 0 | V5: 0 | W5: 0 | X5: 0 | Y5: 0 | Z5: 0 | AA5: 0 | AB5: 0 | AC5: =SUM(B5:AB5) -> 0
A6: 1_2_A7_5 | B6: 0 | C6: 0 | D6: 0 | E6: 0 | F6: 0 | G6: 0 | H6: 0 | I6: 0 | J6: 0 | K6: 0 | L6: 0 | M6: 0 | N6: 0 | O6: 0 | P6: 0 | Q6: 0 | R6: 0 | S6: 0 | T6: 0 | U6: 0 | V6: 0 | W6: 0 | X6: 0 | Y6: 0 | Z6: 0 | AA6: 0 | AB6: 0 | AC6: =SUM(B6:AB6) -> 0
A7: 1_2_A8_6 | B7: 0 | C7: 0 | D7: 0 | E7: 0 | F7: 0 | G7: 0 | H7: 0 | I7: 0 | J7: 0 | K7: 0 | L7: 0 | M7: 0 | N7: 0 | O7: 0 | P7: 0 | Q7: 0 | R7: 0 | S7: 0 | T7: 0 | U7: 0 | V7: 0 | W7: 0 | X7: 0 | Y7: 0 | Z7: 0 | AA7: 0 | AB7: 0 | AC7: =SUM(B7:AB7) -> 0
A8: 1_2_A9_7 | B8: 0 | C8: 0 | D8: 0 | E8: 0 | F8: 0 | G8: 0 | H8: 0 | I8: 0 | J8: 0 | K8: 0 | L8: 0 | M8: 0 | N8: 0 | O8: 0 | P8: 0 | Q8: 0 | R8: 0 | S8: 0 | T8: 0 | U8: 0 | V8: 0 | W8: 0 | X8: 0 | Y8: 0 | Z8: 0 | AA8: 0 | AB8: 0 | AC8: =SUM(B8:AB8) -> 0
A9: 1_2_A10_8 | B9: 0 | C9: 0 | D9: 0 | E9: 0 | F9: 0 | G9: 0 | H9: 0 | I9: 0 | J9: 0 | K9: 0 | L9: 0 | M9: 0 | N9: 0 | O9: 0 | P9: 0 | Q9: 0 | R9: 0 | S9: 0 | T9: 0 | U9: 0 | V9: 0 | W9: 0 | X9: 0 | Y9: 0 | Z9: 0 | AA9: 0 | AB9: 0 | AC9: =SUM(B9:AB9) -> 0
A10: 1_2_A11_9 | B10: 0 | C10: 0 | D10: 0 | E10: 0 | F10: 0 | G10: 0 | H10: 0 | I10: 0 | J10: 0 | K10: 0 | L10: 0 | M10: 0 | N10: 0 | O10: 0 | P10: 0 | Q10: 0 | R10: 0 | S10: 0 | T10: 0 | U10: 0 | V10: 0 | W10: 0 | X10: 0 | Y10: 0 | Z10: 0 | AA10: 0 | AB10: 0 | AC10: =SUM(B10:AB10) -> 0
A11: 1_2_A12_10 | B11: 0 | C11: 0 | D11: 0 | E11: 0 | F11: 0 | G11: 0 | H11: 0 | I11: 0 | J11: 0 | K11: 0 | L11: 0 | M11: 0 | N11: 0 | O11: 0 | P11: 0 | Q11: 0 | R11: 0 | S11: 0 | T11: 0 | U11: 0 | V11: 0 | W11: 0 | X11: 0 | Y11: 0 | Z11: 0 | AA11: 0 | AB11: 0 | AC11: =SUM(B11:AB11) -> 0
A12: Average | B12: =AVERAGE(B2:B11) -> 0 | C12: =AVERAGE(C2:C11) -> 0 | D12: =AVERAGE(D2:D11) -> 0 | E12: =AVERAGE(E2:E11) -> 0 | F12: =AVERAGE(F2:F11) -> 0 | G12: =AVERAGE(G2:G11) -> 0 | H12: =AVERAGE(H2:H11) -> 0 | I12: =AVERAGE(I2:I11) -> 0 | ... AC12: =AVERAGE(AC2:AC11) -> 0
A13: Median | B13: =MEDIAN(B2:B11) -> 0 | C13: =MEDIAN(C2:C11) -> 0 | D13: =MEDIAN(D2:D11) -> 0 | E13: =MEDIAN(E2:E11) -> 0 | F13: =MEDIAN(F2:F11) -> 0 | G13: =MEDIAN(G2:G11) -> 0 | H13: =MEDIAN(H2:H11) -> 0 | I13: =MEDIAN(I2:I11) -> 0 | ... AC13: =MEDIAN(AC2:AC11) -> 0
A14: Mode | B14: =_xlfn.MODE.SNGL(B2:B11) -> 0 | C14: =_xlfn.MODE.SNGL(C2:C11) -> 0 | D14: =_xlfn.MODE.SNGL(D2:D11) -> 0 | E14: =_xlfn.MODE.SNGL(E2:E11) -> 0 | F14: =_xlfn.MODE.SNGL(F2:F11) -> 0 | G14: =_xlfn.MODE.SNGL(G2:G11) -> 0 | H14: =_xlfn.MODE.SNGL(H2:H11) -> 0 | I14: =_xlfn.MODE.SNGL(I2:I11) -> 0 | ... AC14: =_xlfn.MODE.SNGL(AC2:AC11) -> 0
A15: Std dev | B15: =_xlfn.STDEV.P(B2:B11) -> 0 | C15: =_xlfn.STDEV.P(C2:C11) -> 0 | D15: =_xlfn.STDEV.P(D2:D11) -> 0 | E15: =_xlfn.STDEV.P(E2:E11) -> 0 | F15: =_xlfn.STDEV.P(F2:F11) -> 0 | G15: =_xlfn.STDEV.P(G2:G11) -> 0 | H15: =_xlfn.STDEV.P(H2:H11) -> 0 | I15: =_xlfn.STDEV.P(I2:I11) -> 0 | ... AC15: =_xlfn.STDEV.P(AC2:AC11) -> 0

Sheet WT_37
A1: ID | B1: 1 | C1: 2 | D1: 3 | E1: 4 | F1: 5 | G1: 6 | H1: 7 | I1: 8 | J1: 9 | K1: 10 | L1: 11 | M1: 12 | N1: 13 | O1: 14 | P1: 15 | Q1: 16 | R1: 17 | S1: 18 | T1: 19 | U1: 20 | V1: 21 | W1: 22 | X1: 23 | Y1: 24 | Z1: 25 | AA1: 26 | AB1: 27 | AC1: total
A2: 2_1_C3_19 | B2: 0 | C2: 0 | D2: 0 | E2: 0 | F2: 0 | G2: 0 | H2: 0 | I2: 0 | J2: 0 | K2: 0 | L2: 0 | M2: 1 | N2: 0 | O2: 0 | P2: 0 | Q2: 0 | R2: 0 | S2: 0 | T2: 0 | U2: 0 | V2: 0 | W2: 0 | X2: 0 | Y2: 0 | Z2: 0 | AA2: 0 | AB2: 0 | AC2: =SUM(B2:AB2) -> 1
A3: 2_1_C4_27 | B3: 0 | C3: 0 | D3: 0 | E3: 0 | F3: 0 | G3: 0 | H3: 0 | I3: 0 | J3: 0 | K3: 0 | L3: 0 | M3: 0 | N3: 1 | O3: 1 | P3: 0 | Q3: 0 | R3: 0 | S3: 0 | T3: 0 | U3: 0 | V3: 0 | W3: 0 | X3: 0 | Y3: 0 | Z3: 0 | AA3: 0 | AB3: 0 | AC3: =SUM(B3:AB3) -> 2
A4: 2_1_C6_42 | B4: 0 | C4: 0 | D4: 0 | E4: 0 | F4: 0 | G4: 0 | H4: 0 | I4: 0 | J4: 0 | K4: 0 | L4: 0 | M4: 0 | N4: 0 | O4: 1 | P4: 0 | Q4: 0 | R4: 0 | S4: 0 | T4: 0 | U4: 0 | V4: 0 | W4: 0 | X4: 0 | Y4: 0 | Z4: 0 | AA4: 0 | AB4: 0 | AC4: =SUM(B4:AB4) -> 1
A5: 2_1_C7_46 | B5: 0 | C5: 0 | D5: 0 | E5: 0 | F5: 0 | G5: 0 | H5: 0 | I5: 0 | J5: 0 | K5: 0 | L5: 1 | M5: 0 | N5: 0 | O5: 0 | P5: 0 | Q5: 0 | R5: 0 | S5: 0 | T5: 0 | U5: 0 | V5: 0 | W5: 0 | X5: 0 | Y5: 0 | Z5: 0 | AA5: 0 | AB5: 0 | AC5: =SUM(B5:AB5) -> 1
A6: 2_1_C8_52 | B6: 0 | C6: 0 | D6: 0 | E6: 0 | F6: 0 | G6: 0 | H6: 0 | I6: 0 | J6: 0 | K6: 0 | L6: 0 | M6: 1 | N6: 0 | O6: 0 | P6: 0 | Q6: 0 | R6: 0 | S6: 0 | T6: 0 | U6: 0 | V6: 0 | W6: 0 | X6: 0 | Y6: 0 | Z6: 0 | AA6: 0 | AB6: 0 | AC6: =SUM(B6:AB6) -> 1
A7: 2_1_C9_58 | B7: 0 | C7: 0 | D7: 0 | E7: 0 | F7: 0 | G7: 0 | H7: 0 | I7: 0 | J7: 0 | K7: 0 | L7: 0 | M7: 0 | N7: 2 | O7: 0 | P7: 0 | Q7: 0 | R7: 0 | S7: 0 | T7: 0 | U7: 0 | V7: 0 | W7: 0 | X7: 0 | Y7: 0 | Z7: 0 | AA7: 0 | AB7: 0 | AC7: =SUM(B7:AB7) -> 2
A8: 2_1_C10_64 | B8: 0 | C8: 0 | D8: 0 | E8: 0 | F8: 0 | G8: 0 | H8: 0 | I8: 0 | J8: 0 | K8: 0 | L8: 0 | M8: 1 | N8: 0 | O8: 0 | P8: 0 | Q8: 0 | R8: 0 | S8: 0 | T8: 0 | U8: 0 | V8: 0 | W8: 0 | X8: 0 | Y8: 0 | Z8: 0 | AA8: 0 | AB8: 0 | AC8: =SUM(B8:AB8) -> 1
A9: 2_1_C11_69 | B9: 0 | C9: 0 | D9: 0 | E9: 0 | F9: 0 | G9: 0 | H9: 0 | I9: 0 | J9: 0 | K9: 0 | L9: 0 | M9: 0 | N9: 0 | O9: 0 | P9: 0 | Q9: 0 | R9: 0 | S9: 0 | T9: 0 | U9: 0 | V9: 0 | W9: 0 | X9: 0 | Y9: 0 | Z9: 0 | AA9: 0 | AB9: 0 | AC9: =SUM(B9:AB9) -> 0
A10: 2_1_C12_76 | B10: 0 | C10: 0 | D10: 0 | E10: 0 | F10: 0 | G10: 0 | H10: 0 | I10: 0 | J10: 0 | K10: 0 | L10: 0 | M10: 1 | N10: 0 | O10: 0 | P10: 0 | Q10: 0 | R10: 0 | S10: 0 | T10: 0 | U10: 0 | V10: 0 | W10: 0 | X10: 0 | Y10: 0 | Z10: 0 | AA10: 0 | AB10: 0 | AC10: =SUM(B10:AB10) -> 1
A11: 2_1_D1_4 | B11: 0 | C11: 0 | D11: 0 | E11: 0 | F11: 0 | G11: 0 | H11: 0 | I11: 0 | J11: 0 | K11: 0 | L11: 0 | M11: 0 | N11: 0 | O11: 0 | P11: 0 | Q11: 0 | R11: 0 | S11: 0 | T11: 0 | U11: 0 | V11: 0 | W11: 0 | X11: 0 | Y11: 0 | Z11: 0 | AA11: 0 | AB11: 0 | AC11: =SUM(B11:AB11) -> 0
A12: 2_1_D2_12 | B12: 0 | C12: 0 | D12: 0 | E12: 0 | F12: 0 | G12: 0 | H12: 0 | I12: 0 | J12: 0 | K12: 0 | L12: 0 | M12: 0 | N12: 0 | O12: 0 | P12: 0 | Q12: 0 | R12: 0 | S12: 0 | T12: 0 | U12: 0 | V12: 0 | W12: 0 | X12: 0 | Y12: 0 | Z12: 0 | AA12: 0 | AB12: 0 | AC12: =SUM(B12:AB12) -> 0
A13: 2_1_D3_20 | B13: 0 | C13: 0 | D13: 0 | E13: 0 | F13: 0 | G13: 0 | H13: 0 | I13: 0 | J13: 0 | K13: 0 | L13: 0 | M13: 0 | N13: 0 | O13: 1 | P13: 0 | Q13: 0 | R13: 0 | S13: 0 | T13: 0 | U13: 0 | V13: 0 | W13: 0 | X13: 0 | Y13: 0 | Z13: 0 | AA13: 0 | AB13: 0 | AC13: =SUM(B13:AB13) -> 1
... A16: 2_1_D6_43 | B16: 0 | C16: 0 | D16: 0 | E16: 0 | F16: 0 | G16: 0 | H16: 0 | I16: 0 | J16: 0 | K16: 0 | L16: 0 | M16: 0 | N16: 0 | O16: 0 | P16: 0 | Q16: 0 | R16: 0 | S16: 0 | T16: 0 | U16: 0 | V16: 0 | W16: 0 | X16: 0 | Y16: 0 | Z16: 0 | AA16: 0 | AB16: 0 | AC16: =SUM(B16:AB16) -> 0
A17: Average | B17: =AVERAGE(B2:B16) -> 0 | C17: =AVERAGE(C2:C16) -> 0 | D17: =AVERAGE(D2:D16) -> 0 | E17: =AVERAGE(E2:E16) -> 0 | F17: =AVERAGE(F2:F16) -> 0 | G17: =AVERAGE(G2:G16) -> 0 | H17: =AVERAGE(H2:H16) -> 0 | I17: =AVERAGE(I2:I16) -> 0 | ... AC17: =AVERAGE(AC2:AC16) -> 0.8
A18: Median | B18: =MEDIAN(B2:B16) -> 0 | C18: =MEDIAN(C2:C16) -> 0 | D18: =MEDIAN(D2:D16) -> 0 | E18: =MEDIAN(E2:E16) -> 0 | F18: =MEDIAN(F2:F16) -> 0 | G18: =MEDIAN(G2:G16) -> 0 | H18: =MEDIAN(H2:H16) -> 0 | I18: =MEDIAN(I2:I16) -> 0 | ... AC18: =MEDIAN(AC2:AC16) -> 1
A19: Mode | B19: =_xlfn.MODE.SNGL(B2:B16) -> 0 | C19: =_xlfn.MODE.SNGL(C2:C16) -> 0 | D19: =_xlfn.MODE.SNGL(D2:D16) -> 0 | E19: =_xlfn.MODE.SNGL(E2:E16) -> 0 | F19: =_xlfn.MODE.SNGL(F2:F16) -> 0 | G19: =_xlfn.MODE.SNGL(G2:G16) -> 0 | H19: =_xlfn.MODE.SNGL(H2:H16) -> 0 | I19: =_xlfn.MODE.SNGL(I2:I16) -> 0 | ... AC19: =_xlfn.MODE.SNGL(AC2:AC16) -> 1
A20: Std dev | B20: =_xlfn.STDEV.P(B2:B16) -> 0 | C20: =_xlfn.STDEV.P(C2:C16) -> 0 | D20: =_xlfn.STDEV.P(D2:D16) -> 0 | E20: =_xlfn.STDEV.P(E2:E16) -> 0 | F20: =_xlfn.STDEV.P(F2:F16) -> 0 | G20: =_xlfn.STDEV.P(G2:G16) -> 0 | H20: =_xlfn.STDEV.P(H2:H16) -> 0 | I20: =_xlfn.STDEV.P(I2:I16) -> 0 | ... AC20: =_xlfn.STDEV.P(AC2:AC16) -> 0.65319726

Sheet WT_39
A1: ID | B1: 1 | C1: 2 | D1: 3 | E1: 4 | F1: 5 | G1: 6 | H1: 7 | I1: 8 | J1: 9 | K1: 10 | L1: 11 | M1: 12 | N1: 13 | O1: 14 | P1: 15 | Q1: 16 | R1: 17 | S1: 18 | T1: 19 | U1: 20 | V1: 21 | W1: 22 | X1: 23 | Y1: 24 | Z1: 25 | AA1: 26 | AB1: 27 | AC1: total
A2: 1_2_H1_6_V2 | B2: 0 | C2: 0 | D2: 0 | E2: 0 | F2: 0 | G2: 0 | H2: 0 | I2: 0 | J2: 0 | K2: 0 | L2: 0 | M2: 1 | N2: 1 | O2: 0 | P2: 1 | Q2: 0 | R2: 0 | S2: 0 | T2: 0 | U2: 0 | V2: 0 | W2: 0 | X2: 0 | Y2: 0 | Z2: 0 | AA2: 0 | AB2: 0 | AC2: =SUM(B2:AB2) -> 3
A3: 1_2_H3_7_V2 | B3: 0 | C3: 0 | D3: 0 | E3: 0 | F3: 0 | G3: 0 | H3: 0 | I3: 0 | J3: 0 | K3: 0 | L3: 0 | M3: 0 | N3: 2 | O3: 0 | P3: 0 | Q3: 0 | R3: 0 | S3: 0 | T3: 0 | U3: 0 | V3: 0 | W3: 0 | X3: 0 | Y3: 0 | Z3: 0 | AA3: 0 | AB3: 0 | AC3: =SUM(B3:AB3) -> 2
A4: 1_2_H4_8_V2 | B4: 0 | C4: 0 | D4: 0 | E4: 0 | F4: 0 | G4: 0 | H4: 0 | I4: 0 | J4: 0 | K4: 0 | L4: 0 | M4: 0 | N4: 3 | O4: 0 | P4: 0 | Q4: 0 | R4: 0 | S4: 0 | T4: 0 | U4: 0 | V4: 0 | W4: 0 | X4: 0 | Y4: 0 | Z4: 0 | AA4: 0 | AB4: 0 | AC4: =SUM(B4:AB4) -> 3
A5: 1_2_H5_9_V2 | B5: 0 | C5: 0 | D5: 0 | E5: 0 | F5: 0 | G5: 0 | H5: 0 | I5: 0 | J5: 0 | K5: 0 | L5: 0 | M5: 0 | N5: 0 | O5: 0 | P5: 0 | Q5: 0 | R5: 0 | S5: 0 | T5: 0 | U5: 0 | V5: 0 | W5: 0 | X5: 0 | Y5: 0 | Z5: 0 | AA5: 0 | AB5: 0 | AC5: =SUM(B5:AB5) -> 0
A6: 1_2_H6_10_V2 | B6: 0 | C6: 0 | D6: 0 | E6: 0 | F6: 0 | G6: 0 | H6: 0 | I6: 0 | J6: 0 | K6: 0 | L6: 0 | M6: 1 | N6: 0 | O6: 0 | P6: 0 | Q6: 0 | R6: 0 | S6: 0 | T6: 0 | U6: 0 | V6: 0 | W6: 0 | X6: 0 | Y6: 0 | Z6: 0 | AA6: 0 | AB6: 0 | AC6: =SUM(B6:AB6) -> 1
A7: 1_2_H7_11_V2 | B7: 0 | C7: 0 | D7: 0 | E7: 0 | F7: 0 | G7: 0 | H7: 0 | I7: 0 | J7: 0 | K7: 0 | L7: 0 | M7: 2 | N7: 0 | O7: 3 | P7: 0 | Q7: 1 | R7: 0 | S7: 0 | T7: 0 | U7: 0 | V7: 0 | W7: 0 | X7: 0 | Y7: 0 | Z7: 0 | AA7: 0 | AB7: 0 | AC7: =SUM(B7:AB7) -> 6
A8: 1_2_H8_12_V2 | B8: 0 | C8: 0 | D8: 0 | E8: 0 | F8: 0 | G8: 0 | H8: 0 | I8: 0 | J8: 0 | K8: 0 | L8: 0 | M8: 1 | N8: 1 | O8: 0 | P8: 1 | Q8: 0 | R8: 0 | S8: 0 | T8: 0 | U8: 0 | V8: 0 | W8: 0 | X8: 0 | Y8: 0 | Z8: 0 | AA8: 0 | AB8: 0 | AC8: =SUM(B8:AB8) -> 3
A9: 1_2_H9_13_V2 | B9: 0 | C9: 0 | D9: 0 | E9: 0 | F9: 0 | G9: 0 | H9: 0 | I9: 0 | J9: 0 | K9: 0 | L9: 0 | M9: 0 | N9: 0 | O9: 0 | P9: 0 | Q9: 0 | R9: 0 | S9: 0 | T9: 0 | U9: 0 | V9: 0 | W9: 0 | X9: 0 | Y9: 0 | Z9: 0 | AA9: 0 | AB9: 0 | AC9: =SUM(B9:AB9) -> 0
A10: Average | B10: =AVERAGE(B2:B9) -> 0 | C10: =AVERAGE(C2:C9) -> 0 | D10: =AVERAGE(D2:D9) -> 0 | E10: =AVERAGE(E2:E9) -> 0 | F10: =AVERAGE(F2:F9) -> 0 | G10: =AVERAGE(G2:G9) -> 0 | H10: =AVERAGE(H2:H9) -> 0 | I10: =AVERAGE(I2:I9) -> 0 | ... AC10: =AVERAGE(AC2:AC9) -> 2.25
A11: Median | B11: =MEDIAN(B2:B9) -> 0 | C11: =MEDIAN(C2:C9) -> 0 | D11: =MEDIAN(D2:D9) -> 0 | E11: =MEDIAN(E2:E9) -> 0 | F11: =MEDIAN(F2:F9) -> 0 | G11: =MEDIAN(G2:G9) -> 0 | H11: =MEDIAN(H2:H9) -> 0 | I11: =MEDIAN(I2:I9) -> 0 | ... AC11: =MEDIAN(AC2:AC9) -> 2.5
A12: Mode | B12: =_xlfn.MODE.SNGL(B2:B9) -> 0 | C12: =_xlfn.MODE.SNGL(C2:C9) -> 0 | D12: =_xlfn.MODE.SNGL(D2:D9) -> 0 | E12: =_xlfn.MODE.SNGL(E2:E9) -> 0 | F12: =_xlfn.MODE.SNGL(F2:F9) -> 0 | G12: =_xlfn.MODE.SNGL(G2:G9) -> 0 | H12: =_xlfn.MODE.SNGL(H2:H9) -> 0 | I12: =_xlfn.MODE.SNGL(I2:I9) -> 0 | ... AC12: =_xlfn.MODE.SNGL(AC2:AC9) -> 3
A13: Std dev | B13: =_xlfn.STDEV.P(B2:B9) -> 0 | C13: =_xlfn.STDEV.P(C2:C9) -> 0 | D13: =_xlfn.STDEV.P(D2:D9) -> 0 | E13: =_xlfn.STDEV.P(E2:E9) -> 0 | F13: =_xlfn.STDEV.P(F2:F9) -> 0 | G13: =_xlfn.STDEV.P(G2:G9) -> 0 | H13: =_xlfn.STDEV.P(H2:H9) -> 0 | I13: =_xlfn.STDEV.P(I2:I9) -> 0 | ... AC13: =_xlfn.STDEV.P(AC2:AC9) -> 1.8540496

Sheet her1_c
A1: ID | B1: 1 | C1: 2 | D1: 3 | E1: 4 | F1: 5 | G1: 6 | H1: 7 | I1: 8 | J1: 9 | K1: 10 | L1: 11 | M1: 12 | N1: 13 | O1: 14 | P1: 15 | Q1: 16 | R1: 17 | S1: 18 | T1: 19 | U1: 20 | V1: 21 | W1: 22 | X1: 23 | Y1: 24 | Z1: 25 | AA1: 26 | AB1: 27 | AC1: total
A2: 2_1_A1_1 | B2: 0 | C2: 0 | D2: 0 | E2: 0 | F2: 0 | G2: 0 | H2: 0 | I2: 0 | J2: 0 | K2: 0 | L2: 0 | M2: 0 | N2: 0 | O2: 0 | P2: 0 | Q2: 0 | R2: 0 | S2: 0 | T2: 0 | U2: 0 | V2: 0 | W2: 0 | X2: 0 | Y2: 0 | Z2: 0 | AA2: 0 | AB2: 0 | AC2: =SUM(B2:AB2) -> 0
A3: 2_1_A2_9 | B3: 0 | C3: 0 | D3: 0 | E3: 0 | F3: 0 | G3: 1 | H3: 1 | I3: 0 | J3: 0 | K3: 0 | L3: 0 | M3: 0 | N3: 0 | O3: 0 | P3: 0 | Q3: 0 | R3: 0 | S3: 0 | T3: 0 | U3: 0 | V3: 0 | W3: 0 | X3: 0 | Y3: 0 | Z3: 0 | AA3: 0 | AB3: 0 | AC3: =SUM(B3:AB3) -> 2
A4: 2_1_A3_17 | B4: 0 | C4: 0 | D4: 0 | E4: 0 | F4: 0 | G4: 0 | H4: 0 | I4: 0 | J4: 0 | K4: 0 | L4: 0 | M4: 0 | N4: 0 | O4: 0 | P4: 0 | Q4: 0 | R4: 0 | S4: 0 | T4: 0 | U4: 0 | V4: 0 | W4: 0 | X4: 0 | Y4: 0 | Z4: 0 | AA4: 0 | AB4: 0 | AC4: =SUM(B4:AB4) -> 0
A5: 2_1_A4_25 | B5: 0 | C5: 0 | D5: 0 | E5: 0 | F5: 0 | G5: 0 | H5: 0 | I5: 0 | J5: 0 | K5: 0 | L5: 0 | M5: 0 | N5: 0 | O5: 0 | P5: 0 | Q5: 0 | R5: 0 | S5: 0 | T5: 0 | U5: 0 | V5: 0 | W5: 0 | X5: 0 | Y5: 0 | Z5: 0 | AA5: 0 | AB5: 0 | AC5: =SUM(B5:AB5) -> 0
A6: 2_1_A5_33 | B6: 0 | C6: 0 | D6: 0 | E6: 0 | F6: 0 | G6: 0 | H6: 0 | I6: 0 | J6: 0 | K6: 0 | L6: 0 | M6: 0 | N6: 0 | O6: 0 | P6: 0 | Q6: 0 | R6: 0 | S6: 0 | T6: 0 | U6: 0 | V6: 0 | W6: 0 | X6: 0 | Y6: 0 | Z6: 0 | AA6: 0 | AB6: 0 | AC6: =SUM(B6:AB6) -> 0
A7: 2_1_A6_40 | B7: 0 | C7: 0 | D7: 0 | E7: 0 | F7: 0 | G7: 0 | H7: 0 | I7: 0 | J7: 0 | K7: 0 | L7: 0 | M7: 0 | N7: 0 | O7: 0 | P7: 0 | Q7: 0 | R7: 0 | S7: 0 | T7: 0 | U7: 0 | V7: 0 | W7: 0 | X7: 0 | Y7: 0 | Z7: 0 | AA7: 0 | AB7: 0 | AC7: =SUM(B7:AB7) -> 0
A8: 2_1_A7_45 | B8: 0 | C8: 0 | D8: 0 | E8: 0 | F8: 0 | G8: 0 | H8: 0 | I8: 0 | J8: 0 | K8: 0 | L8: 0 | M8: 0 | N8: 0 | O8: 0 | P8: 0 | Q8: 0 | R8: 0 | S8: 0 | T8: 0 | U8: 0 | V8: 0 | W8: 0 | X8: 0 | Y8: 0 | Z8: 0 | AA8: 0 | AB8: 0 | AC8: =SUM(B8:AB8) -> 0
A9: 2_1_A8_51 | B9: 0 | C9: 0 | D9: 0 | E9: 0 | F9: 0 | G9: 0 | H9: 0 | I9: 0 | J9: 0 | K9: 0 | L9: 0 | M9: 0 | N9: 0 | O9: 0 | P9: 0 | Q9: 0 | R9: 0 | S9: 0 | T9: 0 | U9: 0 | V9: 0 | W9: 0 | X9: 0 | Y9: 0 | Z9: 0 | AA9: 0 | AB9: 0 | AC9: =SUM(B9:AB9) -> 0
A10: 2_1_A9_56 | B10: 0 | C10: 0 | D10: 0 | E10: 0 | F10: 0 | G10: 0 | H10: 0 | I10: 0 | J10: 0 | K10: 0 | L10: 0 | M10: 0 | N10: 0 | O10: 0 | P10: 0 | Q10: 0 | R10: 0 | S10: 0 | T10: 0 | U10: 0 | V10: 0 | W10: 0 | X10: 0 | Y10: 0 | Z10: 0 | AA10: 0 | AB10: 0 | AC10: =SUM(B10:AB10) -> 0
A11: 2_1_A10_62 | B11: 0 | C11: 0 | D11: 0 | E11: 0 | F11: 0 | G11: 0 | H11: 0 | I11: 0 | J11: 0 | K11: 0 | L11: 0 | M11: 0 | N11: 0 | O11: 0 | P11: 0 | Q11: 0 | R11: 0 | S11: 0 | T11: 0 | U11: 0 | V11: 0 | W11: 0 | X11: 0 | Y11: 0 | Z11: 0 | AA11: 0 | AB11: 0 | AC11: =SUM(B11:AB11) -> 0
A12: 2_1_A11_68 | B12: 0 | C12: 0 | D12: 0 | E12: 0 | F12: 0 | G12: 0 | H12: 0 | I12: 0 | J12: 0 | K12: 0 | L12: 0 | M12: 0 | N12: 0 | O12: 0 | P12: 0 | Q12: 0 | R12: 0 | S12: 0 | T12: 0 | U12: 0 | V12: 0 | W12: 0 | X12: 0 | Y12: 0 | Z12: 0 | AA12: 0 | AB12: 0 | AC12: =SUM(B12:AB12) -> 0
A13: 2_1_A12_74 | B13: 0 | C13: 0 | D13: 0 | E13: 0 | F13: 0 | G13: 0 | H13: 0 | I13: 0 | J13: 0 | K13: 0 | L13: 0 | M13: 0 | N13: 0 | O13: 0 | P13: 0 | Q13: 0 | R13: 0 | S13: 0 | T13: 0 | U13: 0 | V13: 0 | W13: 0 | X13: 0 | Y13: 0 | Z13: 0 | AA13: 0 | AB13: 0 | AC13: =SUM(B13:AB13) -> 0
... A15: 2_1_B2_10 | B15: 0 | C15: 0 | D15: 0 | E15: 0 | F15: 0 | G15: 0 | H15: 0 | I15: 0 | J15: 0 | K15: 0 | L15: 0 | M15: 0 | N15: 0 | O15: 0 | P15: 0 | Q15: 0 | R15: 0 | S15: 0 | T15: 0 | U15: 0 | V15: 0 | W15: 0 | X15: 0 | Y15: 0 | Z15: 0 | AA15: 0 | AB15: 0 | AC15: =SUM(B15:AB15) -> 0
A16: Average | B16: =AVERAGE(B2:B15) -> 0 | C16: =AVERAGE(C2:C15) -> 0 | D16: =AVERAGE(D2:D15) -> 0 | E16: =AVERAGE(E2:E15) -> 0 | F16: =AVERAGE(F2:F15) -> 0 | G16: =AVERAGE(G2:G15) -> 0.071428571 | H16: =AVERAGE(H2:H15) -> 0.071428571 | I16: =AVERAGE(I2:I15) -> 0 | ... AC16: =AVERAGE(AC2:AC15) -> 0.14285714
A17: Median | B17: =MEDIAN(B2:B15) -> 0 | C17: =MEDIAN(C2:C15) -> 0 | D17: =MEDIAN(D2:D15) -> 0 | E17: =MEDIAN(E2:E15) -> 0 | F17: =MEDIAN(F2:F15) -> 0 | G17: =MEDIAN(G2:G15) -> 0 | H17: =MEDIAN(H2:H15) -> 0 | I17: =MEDIAN(I2:I15) -> 0 | ... AC17: =MEDIAN(AC2:AC15) -> 0
A18: Mode | B18: =_xlfn.MODE.SNGL(B2:B15) -> 0 | C18: =_xlfn.MODE.SNGL(C2:C15) -> 0 | D18: =_xlfn.MODE.SNGL(D2:D15) -> 0 | E18: =_xlfn.MODE.SNGL(E2:E15) -> 0 | F18: =_xlfn.MODE.SNGL(F2:F15) -> 0 | G18: =_xlfn.MODE.SNGL(G2:G15) -> 0 | H18: =_xlfn.MODE.SNGL(H2:H15) -> 0 | I18: =_xlfn.MODE.SNGL(I2:I15) -> 0 | ... AC18: =_xlfn.MODE.SNGL(AC2:AC15) -> 0
A19: Std dev | B19: =_xlfn.STDEV.P(B2:B15) -> 0 | C19: =_xlfn.STDEV.P(C2:C15) -> 0 | D19: =_xlfn.STDEV.P(D2:D15) -> 0 | E19: =_xlfn.STDEV.P(E2:E15) -> 0 | F19: =_xlfn.STDEV.P(F2:F15) -> 0 | G19: =_xlfn.STDEV.P(G2:G15) -> 0.25753938 | H19: =_xlfn.STDEV.P(H2:H15) -> 0.25753938 | I19: =_xlfn.STDEV.P(I2:I15) -> 0 | ... AC19: =_xlfn.STDEV.P(AC2:AC15) -> 0.51507875

Sheet her1_35
A1: ID | B1: 1 | C1: 2 | D1: 3 | E1: 4 | F1: 5 | G1: 6 | H1: 7 | I1: 8 | J1: 9 | K1: 10 | L1: 11 | M1: 12 | N1: 13 | O1: 14 | P1: 15 | Q1: 16 | R1: 17 | S1: 18 | T1: 19 | U1: 20 | V1: 21 | W1: 22 | X1: 23 | Y1: 24 | Z1: 25 | AA1: 26 | AB1: 27 | AC1: total
A2: 2_1_D7_47 | B2: 0 | C2: 0 | D2: 0 | E2: 0 | F2: 0 | G2: 0 | H2: 0 | I2: 0 | J2: 0 | K2: 0 | L2: 0 | M2: 1 | N2: 0 | O2: 0 | P2: 0 | Q2: 0 | R2: 0 | S2: 0 | T2: 0 | U2: 0 | V2: 0 | W2: 0 | X2: 0 | Y2: 0 | Z2: 0 | AA2: 0 | AB2: 0 | AC2: =SUM(B2:AB2) -> 1
A3: 2_1_D10_65 | B3: 0 | C3: 0 | D3: 0 | E3: 0 | F3: 0 | G3: 0 | H3: 0 | I3: 0 | J3: 0 | K3: 0 | L3: 0 | M3: 0 | N3: 0 | O3: 0 | P3: 0 | Q3: 0 | R3: 0 | S3: 0 | T3: 0 | U3: 0 | V3: 0 | W3: 0 | X3: 0 | Y3: 0 | Z3: 0 | AA3: 0 | AB3: 0 | AC3: =SUM(B3:AB3) -> 0
A4: 2_1_D11_70 | B4: 0 | C4: 0 | D4: 0 | E4: 0 | F4: 0 | G4: 0 | H4: 0 | I4: 0 | J4: 0 | K4: 0 | L4: 0 | M4: 1 | N4: 0 | O4: 0 | P4: 0 | Q4: 0 | R4: 0 | S4: 0 | T4: 0 | U4: 0 | V4: 0 | W4: 0 | X4: 0 | Y4: 0 | Z4: 0 | AA4: 0 | AB4: 0 | AC4: =SUM(B4:AB4) -> 1
A5: 2_1_D12_77 | B5: 0 | C5: 0 | D5: 0 | E5: 0 | F5: 0 | G5: 0 | H5: 0 | I5: 0 | J5: 0 | K5: 0 | L5: 0 | M5: 0 | N5: 0 | O5: 0 | P5: 0 | Q5: 0 | R5: 0 | S5: 0 | T5: 0 | U5: 0 | V5: 0 | W5: 0 | X5: 0 | Y5: 0 | Z5: 0 | AA5: 0 | AB5: 0 | AC5: =SUM(B5:AB5) -> 0
A6: 2_1_E2_13 | B6: 0 | C6: 0 | D6: 0 | E6: 0 | F6: 0 | G6: 0 | H6: 0 | I6: 0 | J6: 0 | K6: 0 | L6: 0 | M6: 0 | N6: 0 | O6: 0 | P6: 0 | Q6: 0 | R6: 0 | S6: 0 | T6: 0 | U6: 0 | V6: 0 | W6: 0 | X6: 0 | Y6: 0 | Z6: 0 | AA6: 0 | AB6: 0 | AC6: =SUM(B6:AB6) -> 0
A7: 2_1_E3_21 | B7: 0 | C7: 0 | D7: 0 | E7: 0 | F7: 0 | G7: 0 | H7: 0 | I7: 0 | J7: 0 | K7: 0 | L7: 0 | M7: 0 | N7: 0 | O7: 0 | P7: 0 | Q7: 0 | R7: 0 | S7: 0 | T7: 0 | U7: 0 | V7: 0 | W7: 0 | X7: 0 | Y7: 0 | Z7: 0 | AA7: 0 | AB7: 0 | AC7: =SUM(B7:AB7) -> 0
A8: 2_1_E4_29 | B8: 0 | C8: 0 | D8: 0 | E8: 0 | F8: 0 | G8: 0 | H8: 0 | I8: 0 | J8: 0 | K8: 0 | L8: 0 | M8: 0 | N8: 0 | O8: 0 | P8: 0 | Q8: 0 | R8: 0 | S8: 0 | T8: 0 | U8: 0 | V8: 0 | W8: 0 | X8: 0 | Y8: 0 | Z8: 0 | AA8: 0 | AB8: 0 | AC8: =SUM(B8:AB8) -> 0
A9: 2_1_E5_36 | B9: 0 | C9: 0 | D9: 0 | E9: 0 | F9: 0 | G9: 0 | H9: 0 | I9: 0 | J9: 0 | K9: 0 | L9: 0 | M9: 0 | N9: 0 | O9: 0 | P9: 0 | Q9: 0 | R9: 0 | S9: 0 | T9: 0 | U9: 0 | V9: 0 | W9: 0 | X9: 0 | Y9: 0 | Z9: 0 | AA9: 0 | AB9: 0 | AC9: =SUM(B9:AB9) -> 0
A10: 2_1_E6_44 | B10: 0 | C10: 0 | D10: 0 | E10: 0 | F10: 0 | G10: 0 | H10: 0 | I10: 0 | J10: 0 | K10: 0 | L10: 0 | M10: 0 | N10: 0 | O10: 0 | P10: 0 | Q10: 0 | R10: 0 | S10: 0 | T10: 0 | U10: 0 | V10: 0 | W10: 0 | X10: 0 | Y10: 0 | Z10: 0 | AA10: 0 | AB10: 0 | AC10: =SUM(B10:AB10) -> 0
A11: 2_1_E7_48 | B11: 0 | C11: 0 | D11: 0 | E11: 0 | F11: 0 | G11: 0 | H11: 0 | I11: 0 | J11: 0 | K11: 0 | L11: 1 | M11: 0 | N11: 0 | O11: 0 | P11: 0 | Q11: 0 | R11: 0 | S11: 0 | T11: 0 | U11: 0 | V11: 0 | W11: 0 | X11: 0 | Y11: 0 | Z11: 0 | AA11: 0 | AB11: 0 | AC11: =SUM(B11:AB11) -> 1
A12: 2_1_E8_53 | B12: 0 | C12: 0 | D12: 0 | E12: 0 | F12: 0 | G12: 0 | H12: 0 | I12: 0 | J12: 0 | K12: 0 | L12: 0 | M12: 0 | N12: 0 | O12: 0 | P12: 0 | Q12: 0 | R12: 0 | S12: 0 | T12: 0 | U12: 0 | V12: 0 | W12: 0 | X12: 0 | Y12: 0 | Z12: 0 | AA12: 0 | AB12: 0 | AC12: =SUM(B12:AB12) -> 0
A13: 2_1_E9_59 | B13: 0 | C13: 0 | D13: 0 | E13: 0 | F13: 0 | G13: 0 | H13: 0 | I13: 0 | J13: 0 | K13: 0 | L13: 0 | M13: 1 | N13: 0 | O13: 0 | P13: 0 | Q13: 0 | R13: 0 | S13: 0 | T13: 0 | U13: 0 | V13: 0 | W13: 0 | X13: 0 | Y13: 0 | Z13: 0 | AA13: 0 | AB13: 0 | AC13: =SUM(B13:AB13) -> 1
A14: Average | B14: =AVERAGE(B2:B13) -> 0 | C14: =AVERAGE(C2:C13) -> 0 | D14: =AVERAGE(D2:D13) -> 0 | E14: =AVERAGE(E2:E13) -> 0 | F14: =AVERAGE(F2:F13) -> 0 | G14: =AVERAGE(G2:G13) -> 0 | H14: =AVERAGE(H2:H13) -> 0 | I14: =AVERAGE(I2:I13) -> 0 | ... AC14: =AVERAGE(AC2:AC13) -> 0.33333333
A15: Median | B15: =MEDIAN(B2:B13) -> 0 | C15: =MEDIAN(C2:C13) -> 0 | D15: =MEDIAN(D2:D13) -> 0 | E15: =MEDIAN(E2:E13) -> 0 | F15: =MEDIAN(F2:F13) -> 0 | G15: =MEDIAN(G2:G13) -> 0 | H15: =MEDIAN(H2:H13) -> 0 | I15: =MEDIAN(I2:I13) -> 0 | ... AC15: =MEDIAN(AC2:AC13) -> 0
A16: Mode | B16: =_xlfn.MODE.SNGL(B2:B13) -> 0 | C16: =_xlfn.MODE.SNGL(C2:C13) -> 0 | D16: =_xlfn.MODE.SNGL(D2:D13) -> 0 | E16: =_xlfn.MODE.SNGL(E2:E13) -> 0 | F16: =_xlfn.MODE.SNGL(F2:F13) -> 0 | G16: =_xlfn.MODE.SNGL(G2:G13) -> 0 | H16: =_xlfn.MODE.SNGL(H2:H13) -> 0 | I16: =_xlfn.MODE.SNGL(I2:I13) -> 0 | ... AC16: =_xlfn.MODE.SNGL(AC2:AC13) -> 0
A17: Std dev | B17: =_xlfn.STDEV.P(B2:B13) -> 0 | C17: =_xlfn.STDEV.P(C2:C13) -> 0 | D17: =_xlfn.STDEV.P(D2:D13) -> 0 | E17: =_xlfn.STDEV.P(E2:E13) -> 0 | F17: =_xlfn.STDEV.P(F2:F13) -> 0 | G17: =_xlfn.STDEV.P(G2:G13) -> 0 | H17: =_xlfn.STDEV.P(H2:H13) -> 0 | I17: =_xlfn.STDEV.P(I2:I13) -> 0 | ... AC17: =_xlfn.STDEV.P(AC2:AC13) -> 0.47140452

Sheet her1_37
A1: ID | B1: 1 | C1: 2 | D1: 3 | E1: 4 | F1: 5 | G1: 6 | H1: 7 | I1: 8 | J1: 9 | K1: 10 | L1: 11 | M1: 12 | N1: 13 | O1: 14 | P1: 15 | Q1: 16 | R1: 17 | S1: 18 | T1: 19 | U1: 20 | V1: 21 | W1: 22 | X1: 23 | Y1: 24 | Z1: 25 | AA1: 26 | AB1: 27 | AC1: total
A2: 2_1_E11_71 | B2: 0 | C2: 0 | D2: 0 | E2: 0 | F2: 0 | G2: 0 | H2: 0 | I2: 0 | J2: 0 | K2: 0 | L2: 1 | M2: 1 | N2: 0 | O2: 0 | P2: 1 | Q2: 0 | R2: 0 | S2: 0 | T2: 0 | U2: 0 | V2: 0 | W2: 0 | X2: 0 | Y2: 0 | Z2: 0 | AA2: 0 | AB2: 0 | AC2: =SUM(B2:AB2) -> 3
A3: 2_1_E12_78 | B3: 0 | C3: 0 | D3: 0 | E3: 0 | F3: 0 | G3: 0 | H3: 0 | I3: 0 | J3: 0 | K3: 0 | L3: 0 | M3: 1 | N3: 1 | O3: 0 | P3: 0 | Q3: 0 | R3: 0 | S3: 0 | T3: 0 | U3: 0 | V3: 0 | W3: 0 | X3: 0 | Y3: 0 | Z3: 0 | AA3: 0 | AB3: 0 | AC3: =SUM(B3:AB3) -> 2
A4: 2_1_F1_6 | B4: 0 | C4: 0 | D4: 0 | E4: 0 | F4: 0 | G4: 0 | H4: 0 | I4: 0 | J4: 0 | K4: 0 | L4: 0 | M4: 0 | N4: 0 | O4: 0 | P4: 0 | Q4: 0 | R4: 0 | S4: 0 | T4: 0 | U4: 0 | V4: 0 | W4: 0 | X4: 0 | Y4: 0 | Z4: 0 | AA4: 0 | AB4: 0 | AC4: =SUM(B4:AB4) -> 0
A5: 2_1_F2_14 | B5: 0 | C5: 0 | D5: 0 | E5: 0 | F5: 0 | G5: 0 | H5: 0 | I5: 0 | J5: 0 | K5: 0 | L5: 0 | M5: 0 | N5: 0 | O5: 0 | P5: 0 | Q5: 0 | R5: 0 | S5: 0 | T5: 0 | U5: 0 | V5: 0 | W5: 0 | X5: 0 | Y5: 0 | Z5: 0 | AA5: 0 | AB5: 0 | AC5: =SUM(B5:AB5) -> 0
A6: 2_1_F3_22 | B6: 0 | C6: 0 | D6: 0 | E6: 0 | F6: 0 | G6: 0 | H6: 0 | I6: 0 | J6: 0 | K6: 0 | L6: 1 | M6: 0 | N6: 0 | O6: 0 | P6: 0 | Q6: 0 | R6: 2 | S6: 0 | T6: 0 | U6: 0 | V6: 0 | W6: 0 | X6: 0 | Y6: 0 | Z6: 0 | AA6: 0 | AB6: 0 | AC6: =SUM(B6:AB6) -> 3
A7: 2_1_F4_30 | B7: 0 | C7: 0 | D7: 0 | E7: 0 | F7: 0 | G7: 0 | H7: 0 | I7: 0 | J7: 1 | K7: 1 | L7: 0 | M7: 0 | N7: 0 | O7: 0 | P7: 0 | Q7: 0 | R7: 0 | S7: 0 | T7: 0 | U7: 0 | V7: 0 | W7: 0 | X7: 0 | Y7: 0 | Z7: 0 | AA7: 0 | AB7: 0 | AC7: =SUM(B7:AB7) -> 2
A8: 2_1_F5_37 | B8: 0 | C8: 0 | D8: 0 | E8: 0 | F8: 0 | G8: 0 | H8: 0 | I8: 0 | J8: 0 | K8: 0 | L8: 0 | M8: 0 | N8: 0 | O8: 0 | P8: 0 | Q8: 0 | R8: 0 | S8: 0 | T8: 0 | U8: 0 | V8: 0 | W8: 0 | X8: 0 | Y8: 0 | Z8: 0 | AA8: 0 | AB8: 0 | AC8: =SUM(B8:AB8) -> 0
A9: 2_1_F7_49 | B9: 0 | C9: 0 | D9: 0 | E9: 0 | F9: 0 | G9: 0 | H9: 0 | I9: 0 | J9: 0 | K9: 0 | L9: 1 | M9: 2 | N9: 1 | O9: 1 | P9: 1 | Q9: 1 | R9: 0 | S9: 0 | T9: 0 | U9: 0 | V9: 0 | W9: 0 | X9: 0 | Y9: 0 | Z9: 0 | AA9: 0 | AB9: 0 | AC9: =SUM(B9:AB9) -> 7
A10: 2_1_F8_54 | B10: 0 | C10: 0 | D10: 0 | E10: 0 | F10: 0 | G10: 0 | H10: 0 | I10: 0 | J10: 0 | K10: 0 | L10: 2 | M10: 3 | N10: 2 | O10: 2 | P10: 1 | Q10: 0 | R10: 0 | S10: 0 | T10: 0 | U10: 0 | V10: 0 | W10: 0 | X10: 0 | Y10: 0 | Z10: 0 | AA10: 0 | AB10: 0 | AC10: =SUM(B10:AB10) -> 10
A11: 2_1_F9_60 | B11: 0 | C11: 0 | D11: 0 | E11: 0 | F11: 0 | G11: 0 | H11: 0 | I11: 0 | J11: 0 | K11: 0 | L11: 0 | M11: 0 | N11: 1 | O11: 1 | P11: 0 | Q11: 0 | R11: 0 | S11: 0 | T11: 0 | U11: 0 | V11: 0 | W11: 0 | X11: 0 | Y11: 0 | Z11: 0 | AA11: 0 | AB11: 0 | AC11: =SUM(B11:AB11) -> 2
A12: 2_1_F10_66 | B12: 0 | C12: 0 | D12: 0 | E12: 0 | F12: 0 | G12: 0 | H12: 0 | I12: 0 | J12: 0 | K12: 0 | L12: 0 | M12: 0 | N12: 0 | O12: 0 | P12: 0 | Q12: 0 | R12: 0 | S12: 0 | T12: 0 | U12: 0 | V12: 0 | W12: 0 | X12: 0 | Y12: 0 | Z12: 0 | AA12: 0 | AB12: 0 | AC12: =SUM(B12:AB12) -> 0
A13: 2_1_F11_72 | B13: 0 | C13: 0 | D13: 0 | E13: 0 | F13: 0 | G13: 0 | H13: 0 | I13: 0 | J13: 0 | K13: 0 | L13: 1 | M13: 0 | N13: 0 | O13: 1 | P13: 0 | Q13: 0 | R13: 0 | S13: 0 | T13: 0 | U13: 0 | V13: 0 | W13: 0 | X13: 0 | Y13: 0 | Z13: 0 | AA13: 0 | AB13: 0 | AC13: =SUM(B13:AB13) -> 2
... A15: 2_1_G1_7 | B15: 0 | C15: 0 | D15: 0 | E15: 0 | F15: 0 | G15: 0 | H15: 0 | I15: 0 | J15: 0 | K15: 0 | L15: 1 | M15: 0 | N15: 2 | O15: 1 | P15: 0 | Q15: 0 | R15: 0 | S15: 0 | T15: 0 | U15: 0 | V15: 0 | W15: 0 | X15: 0 | Y15: 0 | Z15: 0 | AA15: 0 | AB15: 0 | AC15: =SUM(B15:AB15) -> 4
A16: Average | B16: =AVERAGE(B4:B15) -> 0 | C16: =AVERAGE(C4:C15) -> 0 | D16: =AVERAGE(D4:D15) -> 0 | E16: =AVERAGE(E4:E15) -> 0 | F16: =AVERAGE(F4:F15) -> 0 | G16: =AVERAGE(G4:G15) -> 0 | H16: =AVERAGE(H4:H15) -> 0 | I16: =AVERAGE(I4:I15) -> 0 | ... AC16: =AVERAGE(AC4:AC15) -> 3
A17: Median | B17: =MEDIAN(B4:B15) -> 0 | C17: =MEDIAN(C4:C15) -> 0 | D17: =MEDIAN(D4:D15) -> 0 | E17: =MEDIAN(E4:E15) -> 0 | F17: =MEDIAN(F4:F15) -> 0 | G17: =MEDIAN(G4:G15) -> 0 | H17: =MEDIAN(H4:H15) -> 0 | I17: =MEDIAN(I4:I15) -> 0 | ... AC17: =MEDIAN(AC4:AC15) -> 2
A18: Mode | B18: =_xlfn.MODE.SNGL(B4:B15) -> 0 | C18: =_xlfn.MODE.SNGL(C4:C15) -> 0 | D18: =_xlfn.MODE.SNGL(D4:D15) -> 0 | E18: =_xlfn.MODE.SNGL(E4:E15) -> 0 | F18: =_xlfn.MODE.SNGL(F4:F15) -> 0 | G18: =_xlfn.MODE.SNGL(G4:G15) -> 0 | H18: =_xlfn.MODE.SNGL(H4:H15) -> 0 | I18: =_xlfn.MODE.SNGL(I4:I15) -> 0 | ... AC18: =_xlfn.MODE.SNGL(AC4:AC15) -> 0
A19: Std dev | B19: =_xlfn.STDEV.P(B4:B15) -> 0 | C19: =_xlfn.STDEV.P(C4:C15) -> 0 | D19: =_xlfn.STDEV.P(D4:D15) -> 0 | E19: =_xlfn.STDEV.P(E4:E15) -> 0 | F19: =_xlfn.STDEV.P(F4:F15) -> 0 | G19: =_xlfn.STDEV.P(G4:G15) -> 0 | H19: =_xlfn.STDEV.P(H4:H15) -> 0 | I19: =_xlfn.STDEV.P(I4:I15) -> 0 | ... AC19: =_xlfn.STDEV.P(AC4:AC15) -> 3.082207

Sheet her1_39
A1: ID | B1: 1 | C1: 2 | D1: 3 | E1: 4 | F1: 5 | G1: 6 | H1: 7 | I1: 8 | J1: 9 | K1: 10 | L1: 11 | M1: 12 | N1: 13 | O1: 14 | P1: 15 | Q1: 16 | R1: 17 | S1: 18 | T1: 19 | U1: 20 | V1: 21 | W1: 22 | X1: 23 | Y1: 24 | Z1: 25 | AA1: 26 | AB1: 27 | AC1: total
A2: 2_1_G2_15 | B2: 0 | C2: 0 | D2: 0 | E2: 0 | F2: 0 | G2: 0 | H2: 0 | I2: 0 | J2: 0 | K2: 1 | L2: 0 | M2: 0 | N2: 0 | O2: 0 | P2: 0 | Q2: 0 | R2: 0 | S2: 0 | T2: 0 | U2: 0 | V2: 0 | W2: 0 | X2: 0 | Y2: 0 | Z2: 0 | AA2: 0 | AB2: 0 | AC2: =SUM(B2:AB2) -> 1
A3: 2_1_G3_23 | B3: 0 | C3: 0 | D3: 0 | E3: 0 | F3: 0 | G3: 0 | H3: 0 | I3: 0 | J3: 0 | K3: 0 | L3: 1 | M3: 0 | N3: 1 | O3: 2 | P3: 2 | Q3: 1 | R3: 1 | S3: 0 | T3: 0 | U3: 0 | V3: 0 | W3: 0 | X3: 0 | Y3: 0 | Z3: 0 | AA3: 0 | AB3: 0 | AC3: =SUM(B3:AB3) -> 8
A4: 2_1_G4_31 | B4: 0 | C4: 0 | D4: 0 | E4: 0 | F4: 0 | G4: 0 | H4: 0 | I4: 0 | J4: 0 | K4: 0 | L4: 1 | M4: 1 | N4: 2 | O4: 0 | P4: 0 | Q4: 1 | R4: 1 | S4: 0 | T4: 0 | U4: 0 | V4: 0 | W4: 0 | X4: 0 | Y4: 0 | Z4: 0 | AA4: 0 | AB4: 0 | AC4: =SUM(B4:AB4) -> 6
A5: 2_1_G5_38 | B5: 0 | C5: 0 | D5: 0 | E5: 0 | F5: 0 | G5: 0 | H5: 0 | I5: 0 | J5: 0 | K5: 0 | L5: 1 | M5: 2 | N5: 1 | O5: 1 | P5: 0 | Q5: 1 | R5: 1 | S5: 0 | T5: 0 | U5: 0 | V5: 0 | W5: 0 | X5: 0 | Y5: 0 | Z5: 0 | AA5: 0 | AB5: 0 | AC5: =SUM(B5:AB5) -> 7
A6: 2_1_G7_50 | B6: 0 | C6: 0 | D6: 0 | E6: 0 | F6: 0 | G6: 0 | H6: 0 | I6: 0 | J6: 0 | K6: 0 | L6: 1 | M6: 3 | N6: 2 | O6: 1 | P6: 1 | Q6: 0 | R6: 0 | S6: 0 | T6: 0 | U6: 0 | V6: 0 | W6: 0 | X6: 0 | Y6: 0 | Z6: 0 | AA6: 0 | AB6: 0 | AC6: =SUM(B6:AB6) -> 8
A7: 2_1_G8_55 | B7: 0 | C7: 0 | D7: 0 | E7: 0 | F7: 0 | G7: 0 | H7: 0 | I7: 0 | J7: 0 | K7: 0 | L7: 1 | M7: 0 | N7: 1 | O7: 1 | P7: 1 | Q7: 2 | R7: 0 | S7: 0 | T7: 0 | U7: 0 | V7: 0 | W7: 0 | X7: 0 | Y7: 0 | Z7: 0 | AA7: 0 | AB7: 0 | AC7: =SUM(B7:AB7) -> 6
A8: 2_1_G9_61 | B8: 0 | C8: 0 | D8: 0 | E8: 0 | F8: 0 | G8: 0 | H8: 0 | I8: 0 | J8: 0 | K8: 1 | L8: 1 | M8: 2 | N8: 1 | O8: 1 | P8: 0 | Q8: 0 | R8: 0 | S8: 0 | T8: 0 | U8: 0 | V8: 0 | W8: 0 | X8: 0 | Y8: 0 | Z8: 0 | AA8: 0 | AB8: 0 | AC8: =SUM(B8:AB8) -> 6
A9: 2_1_G10_67 | B9: 0 | C9: 0 | D9: 0 | E9: 0 | F9: 0 | G9: 0 | H9: 0 | I9: 0 | J9: 0 | K9: 0 | L9: 3 | M9: 2 | N9: 1 | O9: 1 | P9: 0 | Q9: 0 | R9: 0 | S9: 0 | T9: 0 | U9: 0 | V9: 0 | W9: 0 | X9: 0 | Y9: 0 | Z9: 0 | AA9: 0 | AB9: 0 | AC9: =SUM(B9:AB9) -> 7
A10: 2_1_G11_73 | B10: 0 | C10: 0 | D10: 0 | E10: 0 | F10: 0 | G10: 0 | H10: 0 | I10: 0 | J10: 0 | K10: 0 | L10: 0 | M10: 1 | N10: 2 | O10: 1 | P10: 0 | Q10: 0 | R10: 0 | S10: 0 | T10: 0 | U10: 0 | V10: 0 | W10: 0 | X10: 0 | Y10: 0 | Z10: 0 | AA10: 0 | AB10: 0 | AC10: =SUM(B10:AB10) -> 4
A11: 2_1_G12_80 | B11: 0 | C11: 0 | D11: 0 | E11: 0 | F11: 0 | G11: 0 | H11: 0 | I11: 0 | J11: 0 | K11: 0 | L11: 0 | M11: 2 | N11: 1 | O11: 0 | P11: 1 | Q11: 1 | R11: 0 | S11: 0 | T11: 0 | U11: 0 | V11: 0 | W11: 0 | X11: 0 | Y11: 0 | Z11: 0 | AA11: 0 | AB11: 0 | AC11: =SUM(B11:AB11) -> 5
A12: 2_1_H1_8 | B12: 0 | C12: 0 | D12: 0 | E12: 0 | F12: 0 | G12: 0 | H12: 0 | I12: 0 | J12: 0 | K12: 0 | L12: 0 | M12: 0 | N12: 2 | O12: 3 | P12: 1 | Q12: 0 | R12: 0 | S12: 0 | T12: 0 | U12: 0 | V12: 0 | W12: 0 | X12: 0 | Y12: 0 | Z12: 0 | AA12: 0 | AB12: 0 | AC12: =SUM(B12:AB12) -> 6
A13: 2_1_H2_16 | B13: 0 | C13: 0 | D13: 0 | E13: 0 | F13: 0 | G13: 0 | H13: 0 | I13: 0 | J13: 0 | K13: 0 | L13: 0 | M13: 2 | N13: 2 | O13: 3 | P13: 1 | Q13: 0 | R13: 0 | S13: 0 | T13: 0 | U13: 0 | V13: 0 | W13: 0 | X13: 0 | Y13: 0 | Z13: 0 | AA13: 0 | AB13: 0 | AC13: =SUM(B13:AB13) -> 8
... A16: 2_1_H5_39 | B16: 0 | C16: 0 | D16: 0 | E16: 0 | F16: 0 | G16: 0 | H16: 0 | I16: 0 | J16: 0 | K16: 0 | L16: 1 | M16: 2 | N16: 0 | O16: 0 | P16: 0 | Q16: 0 | R16: 2 | S16: 0 | T16: 0 | U16: 0 | V16: 0 | W16: 0 | X16: 0 | Y16: 0 | Z16: 0 | AA16: 0 | AB16: 0 | AC16: =SUM(B16:AB16) -> 5
A17: Average | B17: =AVERAGE(B2:B16) -> 0 | C17: =AVERAGE(C2:C16) -> 0 | D17: =AVERAGE(D2:D16) -> 0 | E17: =AVERAGE(E2:E16) -> 0 | F17: =AVERAGE(F2:F16) -> 0 | G17: =AVERAGE(G2:G16) -> 0 | H17: =AVERAGE(H2:H16) -> 0 | I17: =AVERAGE(I2:I16) -> 0 | ... AC17: =AVERAGE(AC2:AC16) -> 5.8
A18: Median | B18: =MEDIAN(B2:B16) -> 0 | C18: =MEDIAN(C2:C16) -> 0 | D18: =MEDIAN(D2:D16) -> 0 | E18: =MEDIAN(E2:E16) -> 0 | F18: =MEDIAN(F2:F16) -> 0 | G18: =MEDIAN(G2:G16) -> 0 | H18: =MEDIAN(H2:H16) -> 0 | I18: =MEDIAN(I2:I16) -> 0 | ... AC18: =MEDIAN(AC2:AC16) -> 6
A19: Mode | B19: =_xlfn.MODE.SNGL(B2:B16) -> 0 | C19: =_xlfn.MODE.SNGL(C2:C16) -> 0 | D19: =_xlfn.MODE.SNGL(D2:D16) -> 0 | E19: =_xlfn.MODE.SNGL(E2:E16) -> 0 | F19: =_xlfn.MODE.SNGL(F2:F16) -> 0 | G19: =_xlfn.MODE.SNGL(G2:G16) -> 0 | H19: =_xlfn.MODE.SNGL(H2:H16) -> 0 | I19: =_xlfn.MODE.SNGL(I2:I16) -> 0 | ... AC19: =_xlfn.MODE.SNGL(AC2:AC16) -> 6
A20: Std dev | B20: =_xlfn.STDEV.P(B2:B16) -> 0 | C20: =_xlfn.STDEV.P(C2:C16) -> 0 | D20: =_xlfn.STDEV.P(D2:D16) -> 0 | E20: =_xlfn.STDEV.P(E2:E16) -> 0 | F20: =_xlfn.STDEV.P(F2:F16) -> 0 | G20: =_xlfn.STDEV.P(G2:G16) -> 0 | H20: =_xlfn.STDEV.P(H2:H16) -> 0 | I20: =_xlfn.STDEV.P(I2:I16) -> 0 | ... AC20: =_xlfn.STDEV.P(AC2:AC16) -> 1.9043809

Sheet loop_c
A1: ID | B1: 1 | C1: 2 | D1: 3 | E1: 4 | F1: 5 | G1: 6 | H1: 7 | I1: 8 | J1: 9 | K1: 10 | L1: 11 | M1: 12 | N1: 13 | O1: 14 | P1: 15 | Q1: 16 | R1: 17 | S1: 18 | T1: 19 | U1: 20 | V1: 21 | W1: 22 | X1: 23 | Y1: 24 | Z1: 25 | AA1: 26 | AB1: 27 | AC1: total
A2: 1_1_E1_24 | B2: 0 | C2: 0 | D2: 0 | E2: 0 | F2: 0 | G2: 0 | H2: 0 | I2: 1 | J2: 1 | K2: 2 | L2: 2 | M2: 1 | N2: 0 | O2: 0 | P2: 0 | Q2: 0 | R2: 0 | S2: 0 | T2: 0 | U2: 0 | V2: 0 | W2: 0 | X2: 0 | Y2: 0 | Z2: 0 | AA2: 0 | AB2: 0 | AC2: =SUM(B2:AB2) -> 7
A3: 1_1_E2_25 | B3: 0 | C3: 0 | D3: 0 | E3: 0 | F3: 0 | G3: 0 | H3: 0 | I3: 0 | J3: 1 | K3: 0 | L3: 0 | M3: 0 | N3: 0 | O3: 0 | P3: 0 | Q3: 0 | R3: 0 | S3: 0 | T3: 0 | U3: 0 | V3: 0 | W3: 0 | X3: 0 | Y3: 0 | Z3: 0 | AA3: 0 | AB3: 0 | AC3: =SUM(B3:AB3) -> 1
A4: 1_1_E3_26 | B4: 0 | C4: 0 | D4: 0 | E4: 0 | F4: 0 | G4: 1 | H4: 1 | I4: 1 | J4: 1 | K4: 2 | L4: 0 | M4: 0 | N4: 0 | O4: 0 | P4: 0 | Q4: 0 | R4: 0 | S4: 0 | T4: 0 | U4: 0 | V4: 0 | W4: 0 | X4: 0 | Y4: 0 | Z4: 0 | AA4: 0 | AB4: 0 | AC4: =SUM(B4:AB4) -> 6
A5: 1_1_E4_27 | B5: 0 | C5: 0 | D5: 0 | E5: 0 | F5: 2 | G5: 0 | H5: 1 | I5: 2 | J5: 2 | K5: 1 | L5: 1 | M5: 1 | N5: 0 | O5: 0 | P5: 0 | Q5: 0 | R5: 0 | S5: 0 | T5: 0 | U5: 0 | V5: 0 | W5: 0 | X5: 0 | Y5: 0 | Z5: 0 | AA5: 0 | AB5: 0 | AC5: =SUM(B5:AB5) -> 10
A6: 1_1_E6_29 | B6: 0 | C6: 0 | D6: 0 | E6: 0 | F6: 0 | G6: 0 | H6: 1 | I6: 0 | J6: 0 | K6: 0 | L6: 0 | M6: 0 | N6: 0 | O6: 0 | P6: 0 | Q6: 0 | R6: 0 | S6: 0 | T6: 0 | U6: 0 | V6: 0 | W6: 0 | X6: 0 | Y6: 0 | Z6: 0 | AA6: 0 | AB6: 0 | AC6: =SUM(B6:AB6) -> 1
A7: 1_1_E8_30 | B7: 0 | C7: 0 | D7: 0 | E7: 0 | F7: 0 | G7: 0 | H7: 1 | I7: 1 | J7: 1 | K7: 0 | L7: 1 | M7: 0 | N7: 0 | O7: 0 | P7: 0 | Q7: 0 | R7: 0 | S7: 0 | T7: 0 | U7: 0 | V7: 0 | W7: 0 | X7: 0 | Y7: 0 | Z7: 0 | AA7: 0 | AB7: 0 | AC7: =SUM(B7:AB7) -> 4
A8: 1_1_E9_31 | B8: 0 | C8: 0 | D8: 0 | E8: 0 | F8: 0 | G8: 0 | H8: 1 | I8: 1 | J8: 2 | K8: 0 | L8: 0 | M8: 0 | N8: 0 | O8: 0 | P8: 0 | Q8: 0 | R8: 0 | S8: 0 | T8: 0 | U8: 0 | V8: 0 | W8: 0 | X8: 0 | Y8: 0 | Z8: 0 | AA8: 0 | AB8: 0 | AC8: =SUM(B8:AB8) -> 4
A9: 1_1_E10_32 | B9: 0 | C9: 0 | D9: 0 | E9: 1 | F9: 2 | G9: 1 | H9: 2 | I9: 1 | J9: 1 | K9: 1 | L9: 0 | M9: 0 | N9: 0 | O9: 0 | P9: 0 | Q9: 0 | R9: 0 | S9: 0 | T9: 0 | U9: 0 | V9: 0 | W9: 0 | X9: 0 | Y9: 0 | Z9: 0 | AA9: 0 | AB9: 0 | AC9: =SUM(B9:AB9) -> 9
A10: 1_1_E12_33 | B10: 0 | C10: 0 | D10: 0 | E10: 1 | F10: 0 | G10: 0 | H10: 1 | I10: 1 | J10: 2 | K10: 1 | L10: 1 | M10: 1 | N10: 1 | O10: 0 | P10: 0 | Q10: 0 | R10: 0 | S10: 0 | T10: 0 | U10: 0 | V10: 0 | W10: 0 | X10: 0 | Y10: 0 | Z10: 0 | AA10: 0 | AB10: 0 | AC10: =SUM(B10:AB10) -> 9
A11: Average | B11: =AVERAGE(B2:B10) -> 0 | C11: =AVERAGE(C2:C10) -> 0 | D11: =AVERAGE(D2:D10) -> 0 | E11: =AVERAGE(E2:E10) -> 0.22222222 | F11: =AVERAGE(F2:F10) -> 0.44444444 | G11: =AVERAGE(G2:G10) -> 0.22222222 | H11: =AVERAGE(H2:H10) -> 0.88888889 | I11: =AVERAGE(I2:I10) -> 0.88888889 | ... AC11: =AVERAGE(AC2:AC10) -> 5.6666667
A12: Median | B12: =MEDIAN(B2:B10) -> 0 | C12: =MEDIAN(C2:C10) -> 0 | D12: =MEDIAN(D2:D10) -> 0 | E12: =MEDIAN(E2:E10) -> 0 | F12: =MEDIAN(F2:F10) -> 0 | G12: =MEDIAN(G2:G10) -> 0 | H12: =MEDIAN(H2:H10) -> 1 | I12: =MEDIAN(I2:I10) -> 1 | ... AC12: =MEDIAN(AC2:AC10) -> 6
A13: Mode | B13: =_xlfn.MODE.SNGL(B2:B10) -> 0 | C13: =_xlfn.MODE.SNGL(C2:C10) -> 0 | D13: =_xlfn.MODE.SNGL(D2:D10) -> 0 | E13: =_xlfn.MODE.SNGL(E2:E10) -> 0 | F13: =_xlfn.MODE.SNGL(F2:F10) -> 0 | G13: =_xlfn.MODE.SNGL(G2:G10) -> 0 | H13: =_xlfn.MODE.SNGL(H2:H10) -> 1 | I13: =_xlfn.MODE.SNGL(I2:I10) -> 1 | ... AB13: =_xlfn.MODE.SNGL(AB2:AB10) -> 0
A14: Std dev | B14: =_xlfn.STDEV.P(B2:B10) -> 0 | C14: =_xlfn.STDEV.P(C2:C10) -> 0 | D14: =_xlfn.STDEV.P(D2:D10) -> 0 | E14: =_xlfn.STDEV.P(E2:E10) -> 0.41573971 | F14: =_xlfn.STDEV.P(F2:F10) -> 0.83147942 | G14: =_xlfn.STDEV.P(G2:G10) -> 0.41573971 | H14: =_xlfn.STDEV.P(H2:H10) -> 0.56655772 | I14: =_xlfn.STDEV.P(I2:I10) -> 0.56655772 | ... AC14: =_xlfn.STDEV.P(AC2:AC10) -> 3.197221

Sheet loop_35
